Workbook

Sheet Dashboard_TongQuan
A1: DASHBOARD TỔNG QUAN THEO DÕI TIẾN ĐỘ (HK1/2026-2027)
A2: Giảng viên hướng dẫn: ThS. Lê Viết Thanh | Khoa Công nghệ Thông tin - Trường Đại học Tôn Đức Thắng
A4: TỔNG SỐ NHÓM | B4: NHÓM DỰ ÁN CNTT | C4: NHÓM ĐỒ ÁN TN | D4: NHÓM KHÓA LUẬN | E4: TIẾN ĐỘ TRUNG BÌNH | F4: TỔNG TASK HOÀN TẤT
A5: =COUNTA(B8:B17) -> 10 | B5: =COUNTIF(D8:D17, "Dự án CNTT") + COUNTIF(D8:D17, "Dự án + Đồ án") + COUNTIF(D8:D17, "Dự án + Khóa luận") -> 5 | C5: =COUNTIF(D8:D17, "Đồ án tốt nghiệp") + COUNTIF(D8:D17, "Dự án + Đồ án") -> 4 | D5: =COUNTIF(D8:D17, "Khóa luận tốt nghiệp") + COUNTIF(D8:D17, "Dự án + Khóa luận") -> 2 | E5: =AVERAGE(H8:H17) -> 0.20740741 | F5: =SUM(I8:I17) -> 64
A7: STT | B7: Mã Sheet Nhóm | C7: Tên Đề Tài / Dự Án | D7: Loại Hình Đề Tài | E7: Thành Viên 1 | F7: Thành Viên 2 | G7: GV Hướng Dẫn | H7: % Tiến Độ | I7: Đã Xong | J7: Báo Cáo Sạch | K7: Deadline Nộp | L7: Trạng Thái | M7: 13/09/2026 | N7: 19/09/2026 | O7: 27/09/2026 | P7: 46122
A8: 1 | B8: Nhom_01 | C8: =Nhom_01!C5 -> SO SÁNH HIỆU NĂNG GIỮA WAN TRUYỀN THỐNG (MPLS) VÀ SD-WAN TRONG MẠNG DOANH NGHIỆP | D8: =Nhom_01!C4 -> Dự án CNTT | E8: =Nhom_01!C6 -> Huỳnh Văn Dũng - 52300190 | F8: =Nhom_01!G6 -> Trần Gia hưng | G8: =Nhom_01!G4 -> ThS. Lê Viết Thanh | H8: =Nhom_01!H13 -> 0.77777778 | I8: =Nhom_01!B13 -> 21 | J8: =Nhom_01!G8 -> 2026-11-20 | K8: =Nhom_01!C9 -> 2026-12-04 | L8: =Nhom_01!I13 -> ĐANG ĐÚNG HẠN | M8: x | N8: x | O8: x | P8: x
A9: 2 | B9: Nhom_02 | C9: =Nhom_02!C5 -> SO SÁNH MẠNG WAN TRUYỀN THỐNG VÀ MẠNG TÍCH HỢP SDN VÀ SD-WAN | D9: =Nhom_02!C4 -> Dự án CNTT | E9: =Nhom_02!C6 -> Đỗ Tuấn Khang - 52300207 | F9: =Nhom_02!G6 -> Nguyễn Minh Huy - 52300203 | G9: =Nhom_02!G4 -> ThS. Lê Viết Thanh | H9: =Nhom_02!H13 -> 0.18518519 | I9: =Nhom_02!B13 -> 5 | J9: =Nhom_02!G8 -> 2026-11-20 | K9: =Nhom_02!C9 -> 2026-12-04 | L9: =Nhom_02!I13 -> ĐANG THỰC HIỆN | M9: x | N9: x | O9: x | P9: x
A10: 3 | B10: Nhom_03 | C10: =Nhom_03!C5 -> QUẢN LÝ MẠNG DOANH NGHIỆP TRÊN NỀN TẢNG CLOUD SỬ DỤNG SDN | D10: =Nhom_03!C4 -> Dự án CNTT | E10: =Nhom_03!C6 -> Đỗ Tài Khải Nguyên - 52300230 | F10: =Nhom_03!G6 -> Nguyễn Văn An - 52300172 | G10: =Nhom_03!G4 -> ThS. Lê Viết Thanh | H10: =Nhom_03!H13 -> 0.2962963 | I10: =Nhom_03!B13 -> 8 | J10: =Nhom_03!G8 -> 2026-11-20 | K10: =Nhom_03!C9 -> 2026-12-04 | L10: =Nhom_03!I13 -> ĐANG THỰC HIỆN | M10: x | N10: x | O10: x
A11: 4 | B11: Nhom_04 | C11: =Nhom_04!C5 -> Xây dựng Campus Network sử dụng SDN và SD-WAN | D11: =Nhom_04!C4 -> Dự án CNTT | E11: =Nhom_04!C6 -> Trần Hữu Nhân-52300235 | F11: =Nhom_04!G6 -> Nguyễn Nhật Hào- 52300198 | G11: =Nhom_04!G4 -> ThS. Lê Viết Thanh | H11: =Nhom_04!H13 -> 0.2962963 | I11: =Nhom_04!B13 -> 8 | J11: =Nhom_04!G8 -> 2026-11-20 | K11: =Nhom_04!C9 -> 2026-12-04 | L11: =Nhom_04!I13 -> ĐANG THỰC HIỆN | M11: x | N11: x | O11: x | P11: x
A12: 5 | B12: Nhom_05 | C12: =Nhom_05!C5 -> Tự động hóa mạng doanh nghiệp dựa trên Intent cho LAN, VLAN và SD-WAN sử dụng trí tuệ nhân tạo | D12: =Nhom_05!C4 -> Đồ án tốt nghiệp | E12: =Nhom_05!C6 -> Nguyễn Đăng Khoa - 52300210 | F12: =Nhom_05!G6 -> [Họ tên SV 2 - MSSV] | G12: =Nhom_05!G4 -> ThS. Lê Viết Thanh | H12: =Nhom_05!H13 -> 0.11111111 | I12: =Nhom_05!B13 -> 3 | J12: =Nhom_05!G8 -> 2026-12-10 | K12: =Nhom_05!C9 -> 2026-12-27 | L12: =Nhom_05!I13 -> ĐANG THỰC HIỆN | M12: x | N12: x | O12: x | P12: x
A13: 6 | B13: Nhom_06 | C13: =Nhom_06!C5 -> [Nhóm 06 - Điền tên đề tài tại đây] | D13: =Nhom_06!C4 -> Đồ án tốt nghiệp | E13: =Nhom_06!C6 -> [Họ tên SV 1 - MSSV] | F13: =Nhom_06!G6 -> [Họ tên SV 2 - MSSV] | G13: =Nhom_06!G4 -> ThS. Lê Viết Thanh | H13: =Nhom_06!H13 -> 0 | I13: =Nhom_06!B13 -> 0 | J13: =Nhom_06!G8 -> 2026-12-10 | K13: =Nhom_06!C9 -> 2026-12-27 | L13: =Nhom_06!I13 -> ĐANG THỰC HIỆN
A14: 7 | B14: Nhom_07 | C14: =Nhom_07!C11 -> Tự động hóa cấu hình VLAN và SD-WAN theo mô hình Intent sử dụng AI, Python và SDN | D14: =Nhom_07!C4 -> Dự án + Đồ án | E14: =Nhom_07!C6 -> Võ Anh Khoa - 52300211 | F14: =Nhom_07!G6 -> Đặng Ngọc Kim Khánh - 52300208 | G14: =Nhom_07!G4 -> ThS. Lê Viết Thanh | H14: =Nhom_07!H18 -> 0.2962963 | I14: =Nhom_07!B18 -> 16 | J14: =Nhom_07!G8 -> 2026-11-20 | K14: =Nhom_07!C9 -> 2026-12-04 | L14: =Nhom_07!I18 -> ĐANG THỰC HIỆN | M14: x | N14: XP | O14: x
A15: 8 | B15: Nhom_08 | C15: =Nhom_08!C5 -> [Nhóm 08 - Điền tên đề tài tại đây] | D15: =Nhom_08!C4 -> Khóa luận tốt nghiệp | E15: =Nhom_08!C6 -> [Họ tên SV 1 - MSSV] | F15: =Nhom_08!G6 -> [Họ tên SV 2 - MSSV] | G15: =Nhom_08!G4 -> ThS. Lê Viết Thanh | H15: =Nhom_08!H13 -> 0 | I15: =Nhom_08!B13 -> 0 | J15: =Nhom_08!G8 -> 2027-01-05 | K15: =Nhom_08!C9 -> 2027-01-25 | L15: =Nhom_08!I13 -> ĐANG THỰC HIỆN
A16: 9 | B16: Nhom_09 | C16: =Nhom_09!C5 -> Mạng doanh nghiệp tự phục hồi sử dụng SD-WAN và cơ chế khôi phục sự cố thông minh | D16: =Nhom_09!C4 -> Khóa luận tốt nghiệp | E16: =Nhom_09!C6 -> Đặng Hoàng Phú - 52300237 | F16: =Nhom_09!G6 -> Tiêu Thế Bảo - 52300180 | G16: =Nhom_09!G4 -> ThS. Lê Viết Thanh | H16: =Nhom_09!H13 -> 0.11111111 | I16: =Nhom_09!B13 -> 3 | J16: =Nhom_09!G8 -> 2027-01-05 | K16: =Nhom_09!C9 -> 2027-01-25 | L16: =Nhom_09!I13 -> ĐANG THỰC HIỆN | M16: x | N16: x | O16: x
A17: 10 | B17: Nhom_10 | C17: =Nhom_10!C5 -> [Nhóm 10 - Điền tên đề tài tại đây] | D17: =Nhom_10!C4 -> Đồ án tốt nghiệp | E17: =Nhom_10!C6 -> [Họ tên SV 1 - MSSV] | F17: =Nhom_10!G6 -> [Họ tên SV 2 - MSSV] | G17: =Nhom_10!G4 -> ThS. Lê Viết Thanh | H17: =Nhom_10!H13 -> 0 | I17: =Nhom_10!B13 -> 0 | J17: =Nhom_10!G8 -> 2026-12-10 | K17: =Nhom_10!C9 -> 2026-12-27 | L17: =Nhom_10!I13 -> ĐANG THỰC HIỆN

Sheet Khung_KeHoach_Chuan
A1: BẢNG DỮ LIỆU CHUẨN KẾ HOẠCH DỰ ÁN - ĐỒ ÁN - KHÓA LUẬN (HK1/2026-2027)
A2: Khoa Công nghệ Thông tin - Trường Đại học Tôn Đức Thắng | GVHD: ThS. Lê Viết Thanh
A4: LOẠI HÌNH ĐỀ TÀI | B4: NGÀY BẮT ĐẦU | C4: BÁO CÁO GIỮA KỲ | D4: BÁO CÁO SẠCH | E4: DEADLINE NỘP CUỐI KỲ | F4: THỜI GIAN DỰ PHÒNG | G4: LỊCH BẢO VỆ / PHẢN BIỆN | H4: HÌNH THỨC ĐÁNH GIÁ
A5: Dự án CNTT | B5: 2026-08-24 | C5: 20/09/2026 – 04/10/2026 | D5: 2026-11-20 | E5: 2026-12-04 | F5: 21/11/2026 – 04/12/2026 | G5: 26/12/2026 – 31/12/2026 | H5: Báo cáo trực tiếp GVPB + Nhập Rubric
A6: Đồ án tốt nghiệp | B6: 2026-08-24 | C6: 20/09/2026 – 04/10/2026 | D6: 2026-12-10 | E6: 2026-12-27 | F6: 11/12/2026 – 27/12/2026 | G6: 13/01/2027 – 18/01/2027 | H6: Bảo vệ trước Hội đồng ĐATN Khoa CNTT
A7: Khóa luận tốt nghiệp | B7: 2026-08-06 | C7: 29/10/2026 – 12/11/2026 | D7: 2027-01-05 | E7: 2027-01-25 | F7: 06/01/2027 – 25/01/2027 | G7: 03/03/2027 – 06/03/2027 | H7: Bảo vệ trước Hội đồng KLTN cấp Trường/Khoa
A9: DANH MỤC 27 HẠNG MỤC CHI TIẾT THEO TỪNG LOẠI HÌNH
A10: Mã Tra Cứu (Key) | B10: Loại Hình | C10: STT | D10: Giai Đoạn | E10: Hạng Mục Công Việc | F10: Nội Dung Chi Tiết Thực Hiện | G10: Bắt Đầu | H10: Hạn Hoàn Thành | I10: Kết Quả Đầu Ra Gợi Ý | J10: Mốc Đặc Biệt
A11: Dự án CNTT_1 | B11: Dự án CNTT | C11: 1 | D11: I. ĐỊNH HƯỚNG & PHƯƠNG PHÁP LUẬN | E11: Xác định bài toán mạng & mục tiêu dự án SDN/SD-WAN | F11: Vấn đề mạng cần giải quyết (định tuyến, QoS, giám sát, bảo mật...); phạm vi topology thử nghiệm | G11: 2026-08-24 | H11: 2026-08-28 | I11: Tuyên bố bài toán + Phạm vi triển khai SDN/SD-WAN v1
A12: Dự án CNTT_2 | B12: Dự án CNTT | C12: 2 | D12: I. ĐỊNH HƯỚNG & PHƯƠNG PHÁP LUẬN | E12: Khảo sát kiến trúc SDN/SD-WAN & giải pháp liên quan | F12: Kiến trúc SDN (control/data plane, OpenFlow), nền tảng SD-WAN thương mại/mã nguồn mở | G12: 2026-08-24 | H12: 2026-09-02 | I12: Bảng khảo sát Related Work + So sánh giải pháp SDN/SD-WAN hiện có
A13: Dự án CNTT_3 | B13: Dự án CNTT | C13: 3 | D13: I. ĐỊNH HƯỚNG & PHƯƠNG PHÁP LUẬN | E13: Chọn SDN controller, công cụ mô phỏng & kiến trúc hệ thống | F13: Controller (ONOS/Ryu/OpenDaylight), công cụ mô phỏng (Mininet/Containerlab/GNS3), giao thức điều khiển | G13: 2026-08-28 | H13: 2026-09-05 | I13: Sơ đồ kiến trúc tổng thể mạng + Tech stack specification
A14: Dự án CNTT_4 | B14: Dự án CNTT | C14: 4 | D14: I. ĐỊNH HƯỚNG & PHƯƠNG PHÁP LUẬN | E14: Lập kế hoạch công việc, phân công & quản trị rủi ro | F14: WBS: dựng testbed, lập trình controller, kiểm thử định tuyến; Git repo & quy ước làm việc | G14: 2026-08-30 | H14: 2026-09-05 | I14: WBS Backlog + Git repo setup + Quy ước làm việc
A15: Dự án CNTT_5 | B15: Dự án CNTT | C15: 5 | D15: II. THIẾT KẾ & CHUẨN BỊ | E15: Thiết kế topology mạng thử nghiệm & luồng điều khiển | F15: Sơ đồ topology SDN/SD-WAN, luồng traffic, cơ chế trao đổi control plane - data plane | G15: 2026-09-06 | H15: 2026-09-12 | I15: Sơ đồ topology mạng + Thiết kế luồng điều khiển v1
A16: Dự án CNTT_6 | B16: Dự án CNTT | C16: 6 | D16: II. THIẾT KẾ & CHUẨN BỊ | E16: Chuẩn bị testbed, controller & công cụ giám sát mạng | F16: Cài đặt Mininet/Containerlab + controller, công cụ sinh traffic (iperf/hping3), giám sát (Wireshark) | G16: 2026-09-06 | H16: 2026-09-12 | I16: Testbed SDN/SD-WAN hoàn chỉnh + Công cụ giám sát
A17: Dự án CNTT_7 | B17: Dự án CNTT | C17: 7 | D17: II. THIẾT KẾ & CHUẨN BỊ | E17: Xây dựng kế hoạch kiểm thử & tiêu chí nghiệm thu | F17: Test plan, kịch bản định tuyến/failover, tiêu chí đánh giá (Latency, Throughput, Packet Loss) | G17: 2026-09-13 | H17: 2026-09-19 | I17: Test plan + Bộ tiêu chí đánh giá + Baseline metrics
A18: Dự án CNTT_8 | B18: Dự án CNTT | C18: 8 | D18: II. THIẾT KẾ & CHUẨN BỊ | E18: Làm Proof of Concept (PoC): điều khiển định tuyến cơ bản qua controller | F18: Cấu hình flow rules cơ bản, kiểm tra khả năng điều khiển luồng traffic qua controller | G18: 2026-09-13 | H18: 2026-09-19 | I18: Bản demo PoC điều khiển SDN chạy được + Báo cáo rủi ro kỹ thuật
A19: Dự án CNTT_9 | B19: Dự án CNTT | C19: 9 | D19: III. TRIỂN KHAI / THỰC NGHIỆM | E19: Xây dựng phiên bản MVP: hệ thống SDN/SD-WAN vận hành cơ bản | F19: Hoàn thành luồng điều khiển - định tuyến - giám sát cơ bản trên toàn bộ topology | G19: 2026-09-20 | H19: 2026-09-26 | I19: Bản MVP: hệ thống SDN/SD-WAN chạy thông luồng cơ bản
A20: Dự án CNTT_10 | B20: Dự án CNTT | C20: 10 | D20: III. TRIỂN KHAI / THỰC NGHIỆM | E20: NỘP BÁO CÁO TIẾN ĐỘ GIỮA KỲ (MỐC KHOA) | F20: Tổng hợp tiến độ thực hiện, nộp phiếu theo dõi có chữ ký GVHD | G20: 2026-09-20 | H20: 2026-10-04 | I20: Phiếu theo dõi có chữ ký GVHD + Báo cáo giữa kỳ ELIT | J20: GIỮA KỲ
A21: Dự án CNTT_11 | B21: Dự án CNTT | C21: 11 | D21: III. TRIỂN KHAI / THỰC NGHIỆM | E21: Phát triển hoàn thiện module định tuyến & chính sách điều khiển | F21: Lập trình logic định tuyến động, chính sách QoS/ưu tiên traffic, xử lý sự kiện mạng | G21: 2026-10-05 | H21: 2026-10-18 | I21: Module định tuyến & chính sách điều khiển hoàn chỉnh trên Git
A22: Dự án CNTT_12 | B22: Dự án CNTT | C22: 12 | D22: III. TRIỂN KHAI / THỰC NGHIỆM | E22: Tích hợp toàn bộ hệ thống & đồng bộ cấu hình mạng | F22: Kết nối controller-switch-orchestrator, đồng bộ cấu hình giữa các site SD-WAN | G22: 2026-10-19 | H22: 2026-10-25 | I22: Hệ thống tích hợp hoàn chỉnh (Full System Build)
A23: Dự án CNTT_13 | B23: Dự án CNTT | C23: 13 | D23: III. TRIỂN KHAI / THỰC NGHIỆM | E23: Duy trì Technical Log, Commit history & Bằng chứng | F23: Ghi log cấu hình controller, thay đổi flow rules, biên bản họp định kỳ với GVHD | G23: 2026-09-20 | H23: 2026-10-31 | I23: Thư mục Evidence + Git commit log chuẩn quy cách
A24: Dự án CNTT_14 | B24: Dự án CNTT | C24: 14 | D24: IV. KIỂM THỬ & ĐÁNH GIÁ | E24: Thực thi kiểm thử chức năng hệ thống SDN/SD-WAN | F24: Kiểm tra định tuyến, failover, chính sách QoS, khả năng phản hồi controller | G24: 2026-10-26 | H24: 2026-11-01 | I24: Bảng kết quả test chi tiết + Danh sách lỗi đã xử lý
A25: Dự án CNTT_15 | B25: Dự án CNTT | C25: 15 | D25: IV. KIỂM THỬ & ĐÁNH GIÁ | E25: Kiểm thử hiệu năng, độ trễ & khả năng mở rộng hệ thống | F25: Đo độ trễ xử lý (latency), thông lượng (throughput), khả năng chịu tải | G25: 2026-11-02 | H25: 2026-11-08 | I25: Báo cáo Performance & Scalability testing
A26: Dự án CNTT_16 | B26: Dự án CNTT | C26: 16 | D26: IV. KIỂM THỬ & ĐÁNH GIÁ | E26: Tổng hợp số liệu thực nghiệm & biểu đồ đánh giá hệ thống | F26: Độ trễ định tuyến, thông lượng, tỷ lệ mất gói, so sánh trước/sau khi áp dụng SDN | G26: 2026-11-09 | H26: 2026-11-15 | I26: Bộ biểu đồ kết quả + Bảng so sánh hiệu quả mạng truyền thống và SDN
A27: Dự án CNTT_17 | B27: Dự án CNTT | C27: 17 | D27: IV. KIỂM THỬ & ĐÁNH GIÁ | E27: Đánh giá đạt mục tiêu & ghi nhận hạn chế | F27: Đối chiếu mục tiêu ban đầu, chỉ ra hạn chế & đề xuất hướng cải tiến | G27: 2026-11-12 | H27: 2026-11-18 | I27: Bảng đối chiếu mục tiêu - kết quả đạt được
A28: Dự án CNTT_18 | B28: Dự án CNTT | C28: 18 | D28: V. VIẾT & HOÀN THIỆN BÁO CÁO | E28: Xây dựng dàn ý & viết chương mở đầu, cơ sở lý thuyết | F28: Tổng quan SDN/SD-WAN, cơ sở lý thuyết định tuyến/điều khiển mạng, phát biểu bài toán | G28: 2026-10-26 | H28: 2026-11-08 | I28: Bản thảo Chương 1, 2, 3 hoàn chỉnh
A29: Dự án CNTT_19 | B29: Dự án CNTT | C29: 19 | D29: V. VIẾT & HOÀN THIỆN BÁO CÁO | E29: Viết chương thiết kế hệ thống, triển khai & kết quả thực nghiệm | F29: Kiến trúc mạng, luồng điều khiển, kết quả thực nghiệm, biểu đồ minh họa | G29: 2026-11-09 | H29: 2026-11-18 | I29: Bản thảo Chương 4, 5 đầy đủ sơ đồ và số liệu
A30: Dự án CNTT_20 | B30: Dự án CNTT | C30: 20 | D30: V. VIẾT & HOÀN THIỆN BÁO CÁO | E30: Hoàn thiện bản thảo toàn văn (Draft 100%) | F30: Ghép nối toàn bộ nội dung, rà soát nhất quán thuật ngữ SDN/SD-WAN | G30: 2026-11-16 | H30: 2026-11-20 | I30: Bản thảo báo cáo toàn văn 100%
A31: Dự án CNTT_21 | B31: Dự án CNTT | C31: 21 | D31: V. VIẾT & HOÀN THIỆN BÁO CÁO | E31: Review chéo, xin ý kiến GVHD & chỉnh sửa hoàn thiện | F31: GVHD góp ý tính đúng đắn kỹ thuật mạng, chỉnh sửa văn phong | G31: 2026-11-18 | H31: 2026-11-20 | I31: Biên bản phản hồi góp ý + Bản sửa lần cuối
A32: Dự án CNTT_22 | B32: Dự án CNTT | C32: 22 | D32: V. VIẾT & HOÀN THIỆN BÁO CÁO | E32: CHỐT BÁO CÁO SẠCH (FINAL REPORT) | F32: Khóa nội dung, kiểm tra định dạng chuẩn TDTU, xuất PDF hoàn chỉnh | G32: 2026-11-20 | H32: 2026-11-20 | I32: BÁO CÁO SẠCH FINAL READY TO SUBMIT | J32: BÁO CÁO SẠCH
A33: Dự án CNTT_23 | B33: Dự án CNTT | C33: 23 | D33: VI. ĐÓNG GÓI, BÁO CÁO & ĐÁNH GIÁ RUBRIC | E33: NỘP BÁO CÁO CUỐI KỲ (TURNITIN + ELIT) | F33: Nộp file check đạo văn Turnitin + nộp hệ thống ELIT theo quy định Khoa | G33: 2026-11-24 | H33: 2026-12-04 | I33: Xác nhận nộp bài thành công trên ELIT & Turnitin | J33: NỘP CUỐI KỲ
A34: Dự án CNTT_24 | B34: Dự án CNTT | C34: 24 | D34: VI. ĐÓNG GÓI, BÁO CÁO & ĐÁNH GIÁ RUBRIC | E34: Đóng gói mã nguồn, Demo package, Slide thuyết trình | F34: Video demo hệ thống SDN/SD-WAN vận hành thực tế, source code sạch, slide | G34: 2026-12-05 | H34: 2026-12-15 | I34: Slide báo cáo + Source code package sạch
A35: Dự án CNTT_25 | B35: Dự án CNTT | C35: 25 | D35: VI. ĐÓNG GÓI, BÁO CÁO & ĐÁNH GIÁ RUBRIC | E35: GVHD xác nhận duyệt cho sinh viên ra phản biện | F35: ThS. Lê Viết Thanh xác nhận duyệt đủ điều kiện báo cáo với GVPB | G35: 2026-11-29 | H35: 2026-12-04 | I35: Xác nhận của GVHD trên hệ thống
A36: Dự án CNTT_26 | B36: Dự án CNTT | C36: 26 | D36: VI. ĐÓNG GÓI, BÁO CÁO & ĐÁNH GIÁ RUBRIC | E36: Tập dượt thuyết trình & Chuẩn bị câu hỏi phản biện | F36: Trả lời câu hỏi về lựa chọn kiến trúc SDN/SD-WAN, thuật toán định tuyến, kết quả thực nghiệm | G36: 2026-12-18 | H36: 2026-12-25 | I36: Bộ câu hỏi Q&A + Kịch bản demo trơn tru
A37: Dự án CNTT_27 | B37: Dự án CNTT | C37: 27 | D37: VI. ĐÓNG GÓI, BÁO CÁO & ĐÁNH GIÁ RUBRIC | E37: BÁO CÁO VỚI GVPB & NHẬP ĐIỂM RUBRIC | F37: Báo cáo trực tiếp với GVPB; GVPB và GVHD thống nhất điểm trên Rubric | G37: 2026-12-26 | H37: 2026-12-31 | I37: Hoàn thành bảo vệ & Điểm số Rubric chính thức | J37: BẢO VỆ / ĐÁNH GIÁ
A38: Đồ án tốt nghiệp_1 | B38: Đồ án tốt nghiệp | C38: 1 | D38: I. ĐỊNH HƯỚNG & PHƯƠNG PHÁP LUẬN | E38: Xác định đề tài nghiên cứu ứng dụng ML trong SDN/SD-WAN & phạm vi ĐATN | F38: Bài toán mạng cụ thể (định tuyến thông minh/phát hiện tấn công/tối ưu QoS bằng ML), mục tiêu & phạm vi | G38: 2026-08-24 | H38: 2026-08-31 | I38: Đề cương chi tiết ĐATN + Tuyên bố bài toán & phạm vi ứng dụng ML/SDN
A39: Đồ án tốt nghiệp_2 | B39: Đồ án tốt nghiệp | C39: 2 | D39: I. ĐỊNH HƯỚNG & PHƯƠNG PHÁP LUẬN | E39: Khảo sát tài liệu học thuật về SDN/SD-WAN & các mô hình ML liên quan | F39: Tổng hợp bài báo, giải pháp hiện có; phân tích ưu nhược điểm các phương pháp ML trong quản lý mạng | G39: 2026-08-24 | H39: 2026-09-05 | I39: Báo cáo tổng quan nghiên cứu (Literature Review v1)
A40: Đồ án tốt nghiệp_3 | B40: Đồ án tốt nghiệp | C40: 3 | D40: I. ĐỊNH HƯỚNG & PHƯƠNG PHÁP LUẬN | E40: Đề xuất kiến trúc giải pháp SDN/SD-WAN tích hợp ML | F40: Controller, mô hình ML đề xuất (thuật toán, kiến trúc mạng nơ-ron nếu có), luồng xử lý dữ liệu | G40: 2026-09-01 | H40: 2026-09-08 | I40: Sơ đồ kiến trúc giải pháp đề xuất + Lý giải lựa chọn
A41: Đồ án tốt nghiệp_4 | B41: Đồ án tốt nghiệp | C41: 4 | D41: I. ĐỊNH HƯỚNG & PHƯƠNG PHÁP LUẬN | E41: Lập kế hoạch WBS 18 tuần, phân công & quản trị rủi ro | F41: Phân rã công việc thu thập dữ liệu mạng, huấn luyện mô hình, tích hợp hệ thống; Git repo, Drive | G41: 2026-09-03 | H41: 2026-09-10 | I41: WBS Roadmap 18 tuần + Git repo + Quy chế làm việc
A42: Đồ án tốt nghiệp_5 | B42: Đồ án tốt nghiệp | C42: 5 | D42: II. THIẾT KẾ & CHUẨN BỊ | E42: Thiết kế kiến trúc hệ thống, thuật toán ML & cơ sở dữ liệu mạng | F42: Kiến trúc controller-ML engine, thuật toán xử lý, schema lưu trữ flow/traffic data | G42: 2026-09-08 | H42: 2026-09-19 | I42: Tài liệu đặc tả thiết kế chi tiết (System Architecture)
...

Sheet Nhom_01
A1: BẢNG THEO DÕI TIẾN ĐỘ THỰC HIỆN ĐỀ TÀI - NHÓM 01
A2: Khoa Công nghệ Thông tin - Trường ĐH Tôn Đức Thắng | Học kỳ 1 / Năm học 2026 - 2027
A4: Loại hình đề tài (*): | C4: Dự án CNTT | F4: GV Hướng dẫn: | G4: ThS. Lê Viết Thanh | L4: =IF(OR($C$4="Dự án + Đồ án",$C$4="Dự án + Khóa luận"),"Dự án CNTT",$C$4) -> Dự án CNTT
A5: Tên đề tài / dự án: | C5: SO SÁNH HIỆU NĂNG GIỮA WAN TRUYỀN THỐNG (MPLS) VÀ SD-WAN TRONG MẠNG DOANH NGHIỆP
A6: Sinh viên 1 (Trưởng nhóm): | C6: Huỳnh Văn Dũng - 52300190 | F6: Sinh viên 2: | G6: Trần Gia hưng
A7: Email / SĐT SV 1: | C7: 52300190@student.tdtu.edu.vn | F7: Email / SĐT SV 2: | G7: 52300200@student.tdtu.edu.vn
A8: Ngày bắt đầu: | C8: =VLOOKUP($L$4, Khung_KeHoach_Chuan!$A$5:$H$7, 2, FALSE) -> 2026-08-24 | F8: Báo cáo sạch hoàn tất: | G8: =VLOOKUP($L$4, Khung_KeHoach_Chuan!$A$5:$H$7, 4, FALSE) -> 2026-11-20
A9: Deadline chính thức: | C9: =VLOOKUP($L$4, Khung_KeHoach_Chuan!$A$5:$H$7, 5, FALSE) -> 2026-12-04 | F9: Lịch Phản biện / Bảo vệ: | G9: =VLOOKUP($L$4, Khung_KeHoach_Chuan!$A$5:$H$7, 7, FALSE) -> 26/12/2026 – 31/12/2026
A10: Loại hình thứ 2 (nếu có):
A11: TỔNG QUAN TIẾN ĐỘ THỰC HIỆN CỦA NHÓM
A12: Tổng Hạng Mục | B12: Hoàn Thành | C12: Đang Làm | D12: Chưa Bắt Đầu | F12: Tạm Hoãn | G12: Báo Cáo Sạch | H12: Tỷ Lệ Hoàn Thành | I12: Trạng Thái Chung
A13: =COUNTA(C16:C42) + IF($C$10<>"", COUNTA(C45:C71), 0) -> 27 | B13: =COUNTIF(I16:I42, "Hoàn thành") + IF($C$10<>"", COUNTIF(I45:I71, "Hoàn thành"), 0) -> 21 | C13: =COUNTIF(I16:I42, "Đang thực hiện") + IF($C$10<>"", COUNTIF(I45:I71, "Đang thực hiện"), 0) -> 0 | D13: =COUNTIF(I16:I42, "Chưa bắt đầu") + IF($C$10<>"", COUNTIF(I45:I71, "Chưa bắt đầu"), 0) -> 6 | F13: =COUNTIF(I16:I42, "Tạm hoãn - Bị chặn") + IF($C$10<>"", COUNTIF(I45:I71, "Tạm hoãn - Bị chặn"), 0) -> 0 | G13: =G8 -> 2026-11-20 | H13: =B13/A13 -> 0.77777778 | I13: =IF(H13=1, "ĐÃ HOÀN TẤT", IF(H13>=0.5, "ĐANG ĐÚNG HẠN", IF(F13>0, "CẦN HỖ TRỢ", "ĐANG THỰC HIỆN"))) -> ĐANG ĐÚNG HẠN
A15: STT | B15: Giai Đoạn | C15: Hạng Mục Công Việc | D15: Nội Dung Cần Thực Hiện / Gợi Ý | E15: Nội Dung Nhóm Tự Điền | F15: Bắt Đầu | G15: Hạn Hoàn Thành | H15: Kết Quả Đầu Ra Gợi Ý | I15: Trạng Thái (*) | J15: Người Phụ Trách / Ghi Chú & Link
A16: 1 | B16: =VLOOKUP($L$4&"_"&$A16, Khung_KeHoach_Chuan!$A$11:$J$91, 4, FALSE) -> I. ĐỊNH HƯỚNG & PHƯƠNG PHÁP LUẬN | C16: =VLOOKUP($L$4&"_"&$A16, Khung_KeHoach_Chuan!$A$11:$J$91, 5, FALSE) -> Xác định bài toán mạng & mục tiêu dự án SDN/SD-WAN | D16: =VLOOKUP($L$4&"_"&$A16, Khung_KeHoach_Chuan!$A$11:$J$91, 6, FALSE) -> Vấn đề mạng cần giải quyết (định tuyến, QoS, giám sát, bảo mật...); phạm vi topology thử nghiệm | F16: =VLOOKUP($L$4&"_"&$A16, Khung_KeHoach_Chuan!$A$11:$J$91, 7, FALSE) -> 2026-08-24 | G16: =VLOOKUP($L$4&"_"&$A16, Khung_KeHoach_Chuan!$A$11:$J$91, 8, FALSE) -> 2026-08-28 | H16: =VLOOKUP($L$4&"_"&$A16, Khung_KeHoach_Chuan!$A$11:$J$91, 9, FALSE) -> Tuyên bố bài toán + Phạm vi triển khai SDN/SD-WAN v1 | I16: Hoàn thành
A17: 2 | B17: =VLOOKUP($L$4&"_"&$A17, Khung_KeHoach_Chuan!$A$11:$J$91, 4, FALSE) -> I. ĐỊNH HƯỚNG & PHƯƠNG PHÁP LUẬN | C17: =VLOOKUP($L$4&"_"&$A17, Khung_KeHoach_Chuan!$A$11:$J$91, 5, FALSE) -> Khảo sát kiến trúc SDN/SD-WAN & giải pháp liên quan | D17: =VLOOKUP($L$4&"_"&$A17, Khung_KeHoach_Chuan!$A$11:$J$91, 6, FALSE) -> Kiến trúc SDN (control/data plane, OpenFlow), nền tảng SD-WAN thương mại/mã nguồn mở | F17: =VLOOKUP($L$4&"_"&$A17, Khung_KeHoach_Chuan!$A$11:$J$91, 7, FALSE) -> 2026-08-24 | G17: =VLOOKUP($L$4&"_"&$A17, Khung_KeHoach_Chuan!$A$11:$J$91, 8, FALSE) -> 2026-09-02 | H17: =VLOOKUP($L$4&"_"&$A17, Khung_KeHoach_Chuan!$A$11:$J$91, 9, FALSE) -> Bảng khảo sát Related Work + So sánh giải pháp SDN/SD-WAN hiện có | I17: Hoàn thành
A18: 3 | B18: =VLOOKUP($L$4&"_"&$A18, Khung_KeHoach_Chuan!$A$11:$J$91, 4, FALSE) -> I. ĐỊNH HƯỚNG & PHƯƠNG PHÁP LUẬN | C18: =VLOOKUP($L$4&"_"&$A18, Khung_KeHoach_Chuan!$A$11:$J$91, 5, FALSE) -> Chọn SDN controller, công cụ mô phỏng & kiến trúc hệ thống | D18: =VLOOKUP($L$4&"_"&$A18, Khung_KeHoach_Chuan!$A$11:$J$91, 6, FALSE) -> Controller (ONOS/Ryu/OpenDaylight), công cụ mô phỏng (Mininet/Containerlab/GNS3), giao thức điều khiển | F18: =VLOOKUP($L$4&"_"&$A18, Khung_KeHoach_Chuan!$A$11:$J$91, 7, FALSE) -> 2026-08-28 | G18: =VLOOKUP($L$4&"_"&$A18, Khung_KeHoach_Chuan!$A$11:$J$91, 8, FALSE) -> 2026-09-05 | H18: =VLOOKUP($L$4&"_"&$A18, Khung_KeHoach_Chuan!$A$11:$J$91, 9, FALSE) -> Sơ đồ kiến trúc tổng thể mạng + Tech stack specification | I18: Hoàn thành
A19: 4 | B19: =VLOOKUP($L$4&"_"&$A19, Khung_KeHoach_Chuan!$A$11:$J$91, 4, FALSE) -> I. ĐỊNH HƯỚNG & PHƯƠNG PHÁP LUẬN | C19: =VLOOKUP($L$4&"_"&$A19, Khung_KeHoach_Chuan!$A$11:$J$91, 5, FALSE) -> Lập kế hoạch công việc, phân công & quản trị rủi ro | D19: =VLOOKUP($L$4&"_"&$A19, Khung_KeHoach_Chuan!$A$11:$J$91, 6, FALSE) -> WBS: dựng testbed, lập trình controller, kiểm thử định tuyến; Git repo & quy ước làm việc | F19: =VLOOKUP($L$4&"_"&$A19, Khung_KeHoach_Chuan!$A$11:$J$91, 7, FALSE) -> 2026-08-30 | G19: =VLOOKUP($L$4&"_"&$A19, Khung_KeHoach_Chuan!$A$11:$J$91, 8, FALSE) -> 2026-09-05 | H19: =VLOOKUP($L$4&"_"&$A19, Khung_KeHoach_Chuan!$A$11:$J$91, 9, FALSE) -> WBS Backlog + Git repo setup + Quy ước làm việc | I19: Hoàn thành
A20: 5 | B20: =VLOOKUP($L$4&"_"&$A20, Khung_KeHoach_Chuan!$A$11:$J$91, 4, FALSE) -> II. THIẾT KẾ & CHUẨN BỊ | C20: =VLOOKUP($L$4&"_"&$A20, Khung_KeHoach_Chuan!$A$11:$J$91, 5, FALSE) -> Thiết kế topology mạng thử nghiệm & luồng điều khiển | D20: =VLOOKUP($L$4&"_"&$A20, Khung_KeHoach_Chuan!$A$11:$J$91, 6, FALSE) -> Sơ đồ topology SDN/SD-WAN, luồng traffic, cơ chế trao đổi control plane - data plane | F20: =VLOOKUP($L$4&"_"&$A20, Khung_KeHoach_Chuan!$A$11:$J$91, 7, FALSE) -> 2026-09-06 | G20: =VLOOKUP($L$4&"_"&$A20, Khung_KeHoach_Chuan!$A$11:$J$91, 8, FALSE) -> 2026-09-12 | H20: =VLOOKUP($L$4&"_"&$A20, Khung_KeHoach_Chuan!$A$11:$J$91, 9, FALSE) -> Sơ đồ topology mạng + Thiết kế luồng điều khiển v1 | I20: Hoàn thành
A21: 6 | B21: =VLOOKUP($L$4&"_"&$A21, Khung_KeHoach_Chuan!$A$11:$J$91, 4, FALSE) -> II. THIẾT KẾ & CHUẨN BỊ | C21: =VLOOKUP($L$4&"_"&$A21, Khung_KeHoach_Chuan!$A$11:$J$91, 5, FALSE) -> Chuẩn bị testbed, controller & công cụ giám sát mạng | D21: =VLOOKUP($L$4&"_"&$A21, Khung_KeHoach_Chuan!$A$11:$J$91, 6, FALSE) -> Cài đặt Mininet/Containerlab + controller, công cụ sinh traffic (iperf/hping3), giám sát (Wireshark) | F21: =VLOOKUP($L$4&"_"&$A21, Khung_KeHoach_Chuan!$A$11:$J$91, 7, FALSE) -> 2026-09-06 | G21: =VLOOKUP($L$4&"_"&$A21, Khung_KeHoach_Chuan!$A$11:$J$91, 8, FALSE) -> 2026-09-12 | H21: =VLOOKUP($L$4&"_"&$A21, Khung_KeHoach_Chuan!$A$11:$J$91, 9, FALSE) -> Testbed SDN/SD-WAN hoàn chỉnh + Công cụ giám sát | I21: Hoàn thành
A22: 7 | B22: =VLOOKUP($L$4&"_"&$A22, Khung_KeHoach_Chuan!$A$11:$J$91, 4, FALSE) -> II. THIẾT KẾ & CHUẨN BỊ | C22: =VLOOKUP($L$4&"_"&$A22, Khung_KeHoach_Chuan!$A$11:$J$91, 5, FALSE) -> Xây dựng kế hoạch kiểm thử & tiêu chí nghiệm thu | D22: =VLOOKUP($L$4&"_"&$A22, Khung_KeHoach_Chuan!$A$11:$J$91, 6, FALSE) -> Test plan, kịch bản định tuyến/failover, tiêu chí đánh giá (Latency, Throughput, Packet Loss) | F22: =VLOOKUP($L$4&"_"&$A22, Khung_KeHoach_Chuan!$A$11:$J$91, 7, FALSE) -> 2026-09-13 | G22: =VLOOKUP($L$4&"_"&$A22, Khung_KeHoach_Chuan!$A$11:$J$91, 8, FALSE) -> 2026-09-19 | H22: =VLOOKUP($L$4&"_"&$A22, Khung_KeHoach_Chuan!$A$11:$J$91, 9, FALSE) -> Test plan + Bộ tiêu chí đánh giá + Baseline metrics | I22: Hoàn thành
A23: 8 | B23: =VLOOKUP($L$4&"_"&$A23, Khung_KeHoach_Chuan!$A$11:$J$91, 4, FALSE) -> II. THIẾT KẾ & CHUẨN BỊ | C23: =VLOOKUP($L$4&"_"&$A23, Khung_KeHoach_Chuan!$A$11:$J$91, 5, FALSE) -> Làm Proof of Concept (PoC): điều khiển định tuyến cơ bản qua controller | D23: =VLOOKUP($L$4&"_"&$A23, Khung_KeHoach_Chuan!$A$11:$J$91, 6, FALSE) -> Cấu hình flow rules cơ bản, kiểm tra khả năng điều khiển luồng traffic qua controller | F23: =VLOOKUP($L$4&"_"&$A23, Khung_KeHoach_Chuan!$A$11:$J$91, 7, FALSE) -> 2026-09-13 | G23: =VLOOKUP($L$4&"_"&$A23, Khung_KeHoach_Chuan!$A$11:$J$91, 8, FALSE) -> 2026-09-19 | H23: =VLOOKUP($L$4&"_"&$A23, Khung_KeHoach_Chuan!$A$11:$J$91, 9, FALSE) -> Bản demo PoC điều khiển SDN chạy được + Báo cáo rủi ro kỹ thuật | I23: Hoàn thành
A24: 9 | B24: =VLOOKUP($L$4&"_"&$A24, Khung_KeHoach_Chuan!$A$11:$J$91, 4, FALSE) -> III. TRIỂN KHAI / THỰC NGHIỆM | C24: =VLOOKUP($L$4&"_"&$A24, Khung_KeHoach_Chuan!$A$11:$J$91, 5, FALSE) -> Xây dựng phiên bản MVP: hệ thống SDN/SD-WAN vận hành cơ bản | D24: =VLOOKUP($L$4&"_"&$A24, Khung_KeHoach_Chuan!$A$11:$J$91, 6, FALSE) -> Hoàn thành luồng điều khiển - định tuyến - giám sát cơ bản trên toàn bộ topology | F24: =VLOOKUP($L$4&"_"&$A24, Khung_KeHoach_Chuan!$A$11:$J$91, 7, FALSE) -> 2026-09-20 | G24: =VLOOKUP($L$4&"_"&$A24, Khung_KeHoach_Chuan!$A$11:$J$91, 8, FALSE) -> 2026-09-26 | H24: =VLOOKUP($L$4&"_"&$A24, Khung_KeHoach_Chuan!$A$11:$J$91, 9, FALSE) -> Bản MVP: hệ thống SDN/SD-WAN chạy thông luồng cơ bản | I24: Hoàn thành
A25: 10 | B25: =VLOOKUP($L$4&"_"&$A25, Khung_KeHoach_Chuan!$A$11:$J$91, 4, FALSE) -> III. TRIỂN KHAI / THỰC NGHIỆM | C25: =VLOOKUP($L$4&"_"&$A25, Khung_KeHoach_Chuan!$A$11:$J$91, 5, FALSE) -> NỘP BÁO CÁO TIẾN ĐỘ GIỮA KỲ (MỐC KHOA) | D25: =VLOOKUP($L$4&"_"&$A25, Khung_KeHoach_Chuan!$A$11:$J$91, 6, FALSE) -> Tổng hợp tiến độ thực hiện, nộp phiếu theo dõi có chữ ký GVHD | F25: =VLOOKUP($L$4&"_"&$A25, Khung_KeHoach_Chuan!$A$11:$J$91, 7, FALSE) -> 2026-09-20 | G25: =VLOOKUP($L$4&"_"&$A25, Khung_KeHoach_Chuan!$A$11:$J$91, 8, FALSE) -> 2026-10-04 | H25: =VLOOKUP($L$4&"_"&$A25, Khung_KeHoach_Chuan!$A$11:$J$91, 9, FALSE) -> Phiếu theo dõi có chữ ký GVHD + Báo cáo giữa kỳ ELIT | I25: Chưa bắt đầu
A26: 11 | B26: =VLOOKUP($L$4&"_"&$A26, Khung_KeHoach_Chuan!$A$11:$J$91, 4, FALSE) -> III. TRIỂN KHAI / THỰC NGHIỆM | C26: =VLOOKUP($L$4&"_"&$A26, Khung_KeHoach_Chuan!$A$11:$J$91, 5, FALSE) -> Phát triển hoàn thiện module định tuyến & chính sách điều khiển | D26: =VLOOKUP($L$4&"_"&$A26, Khung_KeHoach_Chuan!$A$11:$J$91, 6, FALSE) -> Lập trình logic định tuyến động, chính sách QoS/ưu tiên traffic, xử lý sự kiện mạng | F26: =VLOOKUP($L$4&"_"&$A26, Khung_KeHoach_Chuan!$A$11:$J$91, 7, FALSE) -> 2026-10-05 | G26: =VLOOKUP($L$4&"_"&$A26, Khung_KeHoach_Chuan!$A$11:$J$91, 8, FALSE) -> 2026-10-18 | H26: =VLOOKUP($L$4&"_"&$A26, Khung_KeHoach_Chuan!$A$11:$J$91, 9, FALSE) -> Module định tuyến & chính sách điều khiển hoàn chỉnh trên Git | I26: Hoàn thành
A27: 12 | B27: =VLOOKUP($L$4&"_"&$A27, Khung_KeHoach_Chuan!$A$11:$J$91, 4, FALSE) -> III. TRIỂN KHAI / THỰC NGHIỆM | C27: =VLOOKUP($L$4&"_"&$A27, Khung_KeHoach_Chuan!$A$11:$J$91, 5, FALSE) -> Tích hợp toàn bộ hệ thống & đồng bộ cấu hình mạng | D27: =VLOOKUP($L$4&"_"&$A27, Khung_KeHoach_Chuan!$A$11:$J$91, 6, FALSE) -> Kết nối controller-switch-orchestrator, đồng bộ cấu hình giữa các site SD-WAN | F27: =VLOOKUP($L$4&"_"&$A27, Khung_KeHoach_Chuan!$A$11:$J$91, 7, FALSE) -> 2026-10-19 | G27: =VLOOKUP($L$4&"_"&$A27, Khung_KeHoach_Chuan!$A$11:$J$91, 8, FALSE) -> 2026-10-25 | H27: =VLOOKUP($L$4&"_"&$A27, Khung_KeHoach_Chuan!$A$11:$J$91, 9, FALSE) -> Hệ thống tích hợp hoàn chỉnh (Full System Build) | I27: Hoàn thành
... A42: 27 | B42: =VLOOKUP($L$4&"_"&$A42, Khung_KeHoach_Chuan!$A$11:$J$91, 4, FALSE) -> VI. ĐÓNG GÓI, BÁO CÁO & ĐÁNH GIÁ RUBRIC | C42: =VLOOKUP($L$4&"_"&$A42, Khung_KeHoach_Chuan!$A$11:$J$91, 5, FALSE) -> BÁO CÁO VỚI GVPB & NHẬP ĐIỂM RUBRIC | D42: =VLOOKUP($L$4&"_"&$A42, Khung_KeHoach_Chuan!$A$11:$J$91, 6, FALSE) -> Báo cáo trực tiếp với GVPB; GVPB và GVHD thống nhất điểm trên Rubric | F42: =VLOOKUP($L$4&"_"&$A42, Khung_KeHoach_Chuan!$A$11:$J$91, 7, FALSE) -> 2026-12-26 | G42: =VLOOKUP($L$4&"_"&$A42, Khung_KeHoach_Chuan!$A$11:$J$91, 8, FALSE) -> 2026-12-31 | H42: =VLOOKUP($L$4&"_"&$A42, Khung_KeHoach_Chuan!$A$11:$J$91, 9, FALSE) -> Hoàn thành bảo vệ & Điểm số Rubric chính thức | I42: Chưa bắt đầu
A43: KHỐI CÔNG VIỆC - LOẠI HÌNH THỨ 2 (CHỈ DÙNG NẾU NHÓM LÀM ĐỒNG THỜI 2 LOẠI HÌNH)
A44: STT | B44: Giai Đoạn | C44: Hạng Mục Công Việc | D44: Nội Dung Cần Thực Hiện / Gợi Ý | E44: Nội Dung Nhóm Tự Điền | F44: Bắt Đầu | G44: Hạn Hoàn Thành | H44: Kết Quả Đầu Ra Gợi Ý | I44: Trạng Thái (*) | J44: Người Phụ Trách / Ghi Chú & Link
A45: 1 | B45: =IFERROR(VLOOKUP($C$10&"_"&$A45, Khung_KeHoach_Chuan!$A$11:$J$91, 4, FALSE),"") | C45: =IFERROR(VLOOKUP($C$10&"_"&$A45, Khung_KeHoach_Chuan!$A$11:$J$91, 5, FALSE),"") | D45: =IFERROR(VLOOKUP($C$10&"_"&$A45, Khung_KeHoach_Chuan!$A$11:$J$91, 6, FALSE),"") | F45: =IFERROR(VLOOKUP($C$10&"_"&$A45, Khung_KeHoach_Chuan!$A$11:$J$91, 7, FALSE),"") | G45: =IFERROR(VLOOKUP($C$10&"_"&$A45, Khung_KeHoach_Chuan!$A$11:$J$91, 8, FALSE),"") | H45: =IFERROR(VLOOKUP($C$10&"_"&$A45, Khung_KeHoach_Chuan!$A$11:$J$91, 9, FALSE),"") | I45: Chưa bắt đầu
A46: 2 | B46: =IFERROR(VLOOKUP($C$10&"_"&$A46, Khung_KeHoach_Chuan!$A$11:$J$91, 4, FALSE),"") | C46: =IFERROR(VLOOKUP($C$10&"_"&$A46, Khung_KeHoach_Chuan!$A$11:$J$91, 5, FALSE),"") | D46: =IFERROR(VLOOKUP($C$10&"_"&$A46, Khung_KeHoach_Chuan!$A$11:$J$91, 6, FALSE),"") | F46: =IFERROR(VLOOKUP($C$10&"_"&$A46, Khung_KeHoach_Chuan!$A$11:$J$91, 7, FALSE),"") | G46: =IFERROR(VLOOKUP($C$10&"_"&$A46, Khung_KeHoach_Chuan!$A$11:$J$91, 8, FALSE),"") | H46: =IFERROR(VLOOKUP($C$10&"_"&$A46, Khung_KeHoach_Chuan!$A$11:$J$91, 9, FALSE),"") | I46: Chưa bắt đầu
A47: 3 | B47: =IFERROR(VLOOKUP($C$10&"_"&$A47, Khung_KeHoach_Chuan!$A$11:$J$91, 4, FALSE),"") | C47: =IFERROR(VLOOKUP($C$10&"_"&$A47, Khung_KeHoach_Chuan!$A$11:$J$91, 5, FALSE),"") | D47: =IFERROR(VLOOKUP($C$10&"_"&$A47, Khung_KeHoach_Chuan!$A$11:$J$91, 6, FALSE),"") | F47: =IFERROR(VLOOKUP($C$10&"_"&$A47, Khung_KeHoach_Chuan!$A$11:$J$91, 7, FALSE),"") | G47: =IFERROR(VLOOKUP($C$10&"_"&$A47, Khung_KeHoach_Chuan!$A$11:$J$91, 8, FALSE),"") | H47: =IFERROR(VLOOKUP($C$10&"_"&$A47, Khung_KeHoach_Chuan!$A$11:$J$91, 9, FALSE),"") | I47: Chưa bắt đầu
A48: 4 | B48: =IFERROR(VLOOKUP($C$10&"_"&$A48, Khung_KeHoach_Chuan!$A$11:$J$91, 4, FALSE),"") | C48: =IFERROR(VLOOKUP($C$10&"_"&$A48, Khung_KeHoach_Chuan!$A$11:$J$91, 5, FALSE),"") | D48: =IFERROR(VLOOKUP($C$10&"_"&$A48, Khung_KeHoach_Chuan!$A$11:$J$91, 6, FALSE),"") | F48: =IFERROR(VLOOKUP($C$10&"_"&$A48, Khung_KeHoach_Chuan!$A$11:$J$91, 7, FALSE),"") | G48: =IFERROR(VLOOKUP($C$10&"_"&$A48, Khung_KeHoach_Chuan!$A$11:$J$91, 8, FALSE),"") | H48: =IFERROR(VLOOKUP($C$10&"_"&$A48, Khung_KeHoach_Chuan!$A$11:$J$91, 9, FALSE),"") | I48: Chưa bắt đầu
A49: 5 | B49: =IFERROR(VLOOKUP($C$10&"_"&$A49, Khung_KeHoach_Chuan!$A$11:$J$91, 4, FALSE),"") | C49: =IFERROR(VLOOKUP($C$10&"_"&$A49, Khung_KeHoach_Chuan!$A$11:$J$91, 5, FALSE),"") | D49: =IFERROR(VLOOKUP($C$10&"_"&$A49, Khung_KeHoach_Chuan!$A$11:$J$91, 6, FALSE),"") | F49: =IFERROR(VLOOKUP($C$10&"_"&$A49, Khung_KeHoach_Chuan!$A$11:$J$91, 7, FALSE),"") | G49: =IFERROR(VLOOKUP($C$10&"_"&$A49, Khung_KeHoach_Chuan!$A$11:$J$91, 8, FALSE),"") | H49: =IFERROR(VLOOKUP($C$10&"_"&$A49, Khung_KeHoach_Chuan!$A$11:$J$91, 9, FALSE),"") | I49: Chưa bắt đầu
A50: 6 | B50: =IFERROR(VLOOKUP($C$10&"_"&$A50, Khung_KeHoach_Chuan!$A$11:$J$91, 4, FALSE),"") | C50: =IFERROR(VLOOKUP($C$10&"_"&$A50, Khung_KeHoach_Chuan!$A$11:$J$91, 5, FALSE),"") | D50: =IFERROR(VLOOKUP($C$10&"_"&$A50, Khung_KeHoach_Chuan!$A$11:$J$91, 6, FALSE),"") | F50: =IFERROR(VLOOKUP($C$10&"_"&$A50, Khung_KeHoach_Chuan!$A$11:$J$91, 7, FALSE),"") | G50: =IFERROR(VLOOKUP($C$10&"_"&$A50, Khung_KeHoach_Chuan!$A$11:$J$91, 8, FALSE),"") | H50: =IFERROR(VLOOKUP($C$10&"_"&$A50, Khung_KeHoach_Chuan!$A$11:$J$91, 9, FALSE),"") | I50: Chưa bắt đầu
A51: 7 | B51: =IFERROR(VLOOKUP($C$10&"_"&$A51, Khung_KeHoach_Chuan!$A$11:$J$91, 4, FALSE),"") | C51: =IFERROR(VLOOKUP($C$10&"_"&$A51, Khung_KeHoach_Chuan!$A$11:$J$91, 5, FALSE),"") | D51: =IFERROR(VLOOKUP($C$10&"_"&$A51, Khung_KeHoach_Chuan!$A$11:$J$91, 6, FALSE),"") | F51: =IFERROR(VLOOKUP($C$10&"_"&$A51, Khung_KeHoach_Chuan!$A$11:$J$91, 7, FALSE),"") | G51: =IFERROR(VLOOKUP($C$10&"_"&$A51, Khung_KeHoach_Chuan!$A$11:$J$91, 8, FALSE),"") | H51: =IFERROR(VLOOKUP($C$10&"_"&$A51, Khung_KeHoach_Chuan!$A$11:$J$91, 9, FALSE),"") | I51: Chưa bắt đầu
A52: 8 | B52: =IFERROR(VLOOKUP($C$10&"_"&$A52, Khung_KeHoach_Chuan!$A$11:$J$91, 4, FALSE),"") | C52: =IFERROR(VLOOKUP($C$10&"_"&$A52, Khung_KeHoach_Chuan!$A$11:$J$91, 5, FALSE),"") | D52: =IFERROR(VLOOKUP($C$10&"_"&$A52, Khung_KeHoach_Chuan!$A$11:$J$91, 6, FALSE),"") | F52: =IFERROR(VLOOKUP($C$10&"_"&$A52, Khung_KeHoach_Chuan!$A$11:$J$91, 7, FALSE),"") | G52: =IFERROR(VLOOKUP($C$10&"_"&$A52, Khung_KeHoach_Chuan!$A$11:$J$91, 8, FALSE),"") | H52: =IFERROR(VLOOKUP($C$10&"_"&$A52, Khung_KeHoach_Chuan!$A$11:$J$91, 9, FALSE),"") | I52: Chưa bắt đầu
A53: 9 | B53: =IFERROR(VLOOKUP($C$10&"_"&$A53, Khung_KeHoach_Chuan!$A$11:$J$91, 4, FALSE),"") | C53: =IFERROR(VLOOKUP($C$10&"_"&$A53, Khung_KeHoach_Chuan!$A$11:$J$91, 5, FALSE),"") | D53: =IFERROR(VLOOKUP($C$10&"_"&$A53, Khung_KeHoach_Chuan!$A$11:$J$91, 6, FALSE),"") | F53: =IFERROR(VLOOKUP($C$10&"_"&$A53, Khung_KeHoach_Chuan!$A$11:$J$91, 7, FALSE),"") | G53: =IFERROR(VLOOKUP($C$10&"_"&$A53, Khung_KeHoach_Chuan!$A$11:$J$91, 8, FALSE),"") | H53: =IFERROR(VLOOKUP($C$10&"_"&$A53, Khung_KeHoach_Chuan!$A$11:$J$91, 9, FALSE),"") | I53: Chưa bắt đầu
A54: 10 | B54: =IFERROR(VLOOKUP($C$10&"_"&$A54, Khung_KeHoach_Chuan!$A$11:$J$91, 4, FALSE),"") | C54: =IFERROR(VLOOKUP($C$10&"_"&$A54, Khung_KeHoach_Chuan!$A$11:$J$91, 5, FALSE),"") | D54: =IFERROR(VLOOKUP($C$10&"_"&$A54, Khung_KeHoach_Chuan!$A$11:$J$91, 6, FALSE),"") | F54: =IFERROR(VLOOKUP($C$10&"_"&$A54, Khung_KeHoach_Chuan!$A$11:$J$91, 7, FALSE),"") | G54: =IFERROR(VLOOKUP($C$10&"_"&$A54, Khung_KeHoach_Chuan!$A$11:$J$91, 8, FALSE),"") | H54: =IFERROR(VLOOKUP($C$10&"_"&$A54, Khung_KeHoach_Chuan!$A$11:$J$91, 9, FALSE),"") | I54: Chưa bắt đầu
A55: 11 | B55: =IFERROR(VLOOKUP($C$10&"_"&$A55, Khung_KeHoach_Chuan!$A$11:$J$91, 4, FALSE),"") | C55: =IFERROR(VLOOKUP($C$10&"_"&$A55, Khung_KeHoach_Chuan!$A$11:$J$91, 5, FALSE),"") | D55: =IFERROR(VLOOKUP($C$10&"_"&$A55, Khung_KeHoach_Chuan!$A$11:$J$91, 6, FALSE),"") | F55: =IFERROR(VLOOKUP($C$10&"_"&$A55, Khung_KeHoach_Chuan!$A$11:$J$91, 7, FALSE),"") | G55: =IFERROR(VLOOKUP($C$10&"_"&$A55, Khung_KeHoach_Chuan!$A$11:$J$91, 8, FALSE),"") | H55: =IFERROR(VLOOKUP($C$10&"_"&$A55, Khung_KeHoach_Chuan!$A$11:$J$91, 9, FALSE),"") | I55: Chưa bắt đầu
A56: 12 | B56: =IFERROR(VLOOKUP($C$10&"_"&$A56, Khung_KeHoach_Chuan!$A$11:$J$91, 4, FALSE),"") | C56: =IFERROR(VLOOKUP($C$10&"_"&$A56, Khung_KeHoach_Chuan!$A$11:$J$91, 5, FALSE),"") | D56: =IFERROR(VLOOKUP($C$10&"_"&$A56, Khung_KeHoach_Chuan!$A$11:$J$91, 6, FALSE),"") | F56: =IFERROR(VLOOKUP($C$10&"_"&$A56, Khung_KeHoach_Chuan!$A$11:$J$91, 7, FALSE),"") | G56: =IFERROR(VLOOKUP($C$10&"_"&$A56, Khung_KeHoach_Chuan!$A$11:$J$91, 8, FALSE),"") | H56: =IFERROR(VLOOKUP($C$10&"_"&$A56, Khung_KeHoach_Chuan!$A$11:$J$91, 9, FALSE),"") | I56: Chưa bắt đầu
...

Sheet Nhom_02
A1: BẢNG THEO DÕI TIẾN ĐỘ THỰC HIỆN ĐỀ TÀI - NHÓM 02
A2: Khoa Công nghệ Thông tin - Trường ĐH Tôn Đức Thắng | Học kỳ 1 / Năm học 2026 - 2027
A4: Loại hình đề tài (*): | C4: Dự án CNTT | F4: GV Hướng dẫn: | G4: ThS. Lê Viết Thanh | L4: =IF(OR($C$4="Dự án + Đồ án",$C$4="Dự án + Khóa luận"),"Dự án CNTT",$C$4) -> Dự án CNTT
A5: Tên đề tài / dự án: | C5: SO SÁNH MẠNG WAN TRUYỀN THỐNG VÀ MẠNG TÍCH HỢP SDN VÀ SD-WAN
A6: Sinh viên 1 (Trưởng nhóm): | C6: Đỗ Tuấn Khang - 52300207 | F6: Sinh viên 2: | G6: Nguyễn Minh Huy - 52300203
A7: Email / SĐT SV 1: | C7: 52300207@student.tdtu.edu.vn | F7: Email / SĐT SV 2: | G7: 52300203@student.tdtu.edu.vn
A8: Ngày bắt đầu: | C8: =VLOOKUP($L$4, Khung_KeHoach_Chuan!$A$5:$H$7, 2, FALSE) -> 2026-08-24 | F8: Báo cáo sạch hoàn tất: | G8: =VLOOKUP($L$4, Khung_KeHoach_Chuan!$A$5:$H$7, 4, FALSE) -> 2026-11-20
A9: Deadline chính thức: | C9: =VLOOKUP($L$4, Khung_KeHoach_Chuan!$A$5:$H$7, 5, FALSE) -> 2026-12-04 | F9: Lịch Phản biện / Bảo vệ: | G9: =VLOOKUP($L$4, Khung_KeHoach_Chuan!$A$5:$H$7, 7, FALSE) -> 26/12/2026 – 31/12/2026
A10: Loại hình thứ 2 (nếu có):
A11: TỔNG QUAN TIẾN ĐỘ THỰC HIỆN CỦA NHÓM
A12: Tổng Hạng Mục | B12: Hoàn Thành | C12: Đang Làm | D12: Chưa Bắt Đầu | F12: Tạm Hoãn | G12: Báo Cáo Sạch | H12: Tỷ Lệ Hoàn Thành | I12: Trạng Thái Chung
A13: =COUNTA(C16:C42) + IF($C$10<>"", COUNTA(C45:C71), 0) -> 27 | B13: =COUNTIF(I16:I42, "Hoàn thành") + IF($C$10<>"", COUNTIF(I45:I71, "Hoàn thành"), 0) -> 5 | C13: =COUNTIF(I16:I42, "Đang thực hiện") + IF($C$10<>"", COUNTIF(I45:I71, "Đang thực hiện"), 0) -> 4 | D13: =COUNTIF(I16:I42, "Chưa bắt đầu") + IF($C$10<>"", COUNTIF(I45:I71, "Chưa bắt đầu"), 0) -> 18 | F13: =COUNTIF(I16:I42, "Tạm hoãn - Bị chặn") + IF($C$10<>"", COUNTIF(I45:I71, "Tạm hoãn - Bị chặn"), 0) -> 0 | G13: =G8 -> 2026-11-20 | H13: =B13/A13 -> 0.18518519 | I13: =IF(H13=1, "ĐÃ HOÀN TẤT", IF(H13>=0.5, "ĐANG ĐÚNG HẠN", IF(F13>0, "CẦN HỖ TRỢ", "ĐANG THỰC HIỆN"))) -> ĐANG THỰC HIỆN
A15: STT | B15: Giai Đoạn | C15: Hạng Mục Công Việc | D15: Nội Dung Cần Thực Hiện / Gợi Ý | E15: Nội Dung Nhóm Tự Điền | F15: Bắt Đầu | G15: Hạn Hoàn Thành | H15: Kết Quả Đầu Ra Gợi Ý | I15: Trạng Thái (*) | J15: Người Phụ Trách / Ghi Chú & Link
A16: 1 | B16: =VLOOKUP($L$4&"_"&$A16, Khung_KeHoach_Chuan!$A$11:$J$91, 4, FALSE) -> I. ĐỊNH HƯỚNG & PHƯƠNG PHÁP LUẬN | C16: =VLOOKUP($L$4&"_"&$A16, Khung_KeHoach_Chuan!$A$11:$J$91, 5, FALSE) -> Xác định bài toán mạng & mục tiêu dự án SDN/SD-WAN | D16: =VLOOKUP($L$4&"_"&$A16, Khung_KeHoach_Chuan!$A$11:$J$91, 6, FALSE) -> Vấn đề mạng cần giải quyết (định tuyến, QoS, giám sát, bảo mật...); phạm vi topology thử nghiệm | E16: Bài toán cần giải quyết: WAN truyền thống (MPLS) có chi phí cao, khó mở rộng, tốn thời gian cấu hình thủ công từng thiết bị và thiếu khả năng quản lý, giám sát tập trung. Mục tiêu dự án: Tối ưu hóa hạ tầng mạng bằng cách chuyển đổi/tích hợp mô hình SDN/SD-WAN; tự động hóa việc điều khiển luồng dữ liệu và quản trị tập trung.Phạm vi mô hình: Giả lập mạng gồm 2–3 chi nhánh (Sites) nối về Trung tâm dữ liệu (Data Center) qua các đường truyền song song (MPLS giả lập + Internet). | F16: =VLOOKUP($L$4&"_"&$A16, Khung_KeHoach_Chuan!$A$11:$J$91, 7, FALSE) -> 2026-08-24 | G16: =VLOOKUP($L$4&"_"&$A16, Khung_KeHoach_Chuan!$A$11:$J$91, 8, FALSE) -> 2026-08-28 | H16: =VLOOKUP($L$4&"_"&$A16, Khung_KeHoach_Chuan!$A$11:$J$91, 9, FALSE) -> Tuyên bố bài toán + Phạm vi triển khai SDN/SD-WAN v1 | I16: Hoàn thành
A17: 2 | B17: =VLOOKUP($L$4&"_"&$A17, Khung_KeHoach_Chuan!$A$11:$J$91, 4, FALSE) -> I. ĐỊNH HƯỚNG & PHƯƠNG PHÁP LUẬN | C17: =VLOOKUP($L$4&"_"&$A17, Khung_KeHoach_Chuan!$A$11:$J$91, 5, FALSE) -> Khảo sát kiến trúc SDN/SD-WAN & giải pháp liên quan | D17: =VLOOKUP($L$4&"_"&$A17, Khung_KeHoach_Chuan!$A$11:$J$91, 6, FALSE) -> Kiến trúc SDN (control/data plane, OpenFlow), nền tảng SD-WAN thương mại/mã nguồn mở | E17: Kiến trúc SDN: Phân tách rõ 3 mặt phẳng gồm Data Plane (chuyển tiếp dữ liệu qua OpenFlow), Control Plane (bộ điều khiển tập trung) và Application Plane (các ứng dụng quản trị, QoS, bảo mật). Công nghệ SD-WAN: Sử dụng mạng ảo (Overlay Tunnel), chọn đường đi linh hoạt dựa trên chất lượng đường truyền (Dynamic Path Selection) và quản lý tập trung qua bảng điều khiển. Giải pháp khảo sát: Khảo sát các nền tảng mã nguồn mở OpenDaylight, ONOS, Mininet và tham khảo tài liệu các giải pháp thương mại (Cisco Viptela, Fortinet, VMware VeloCloud). | F17: =VLOOKUP($L$4&"_"&$A17, Khung_KeHoach_Chuan!$A$11:$J$91, 7, FALSE) -> 2026-08-24 | G17: =VLOOKUP($L$4&"_"&$A17, Khung_KeHoach_Chuan!$A$11:$J$91, 8, FALSE) -> 2026-09-02 | H17: =VLOOKUP($L$4&"_"&$A17, Khung_KeHoach_Chuan!$A$11:$J$91, 9, FALSE) -> Bảng khảo sát Related Work + So sánh giải pháp SDN/SD-WAN hiện có | I17: Hoàn thành
A18: 3 | B18: =VLOOKUP($L$4&"_"&$A18, Khung_KeHoach_Chuan!$A$11:$J$91, 4, FALSE) -> I. ĐỊNH HƯỚNG & PHƯƠNG PHÁP LUẬN | C18: =VLOOKUP($L$4&"_"&$A18, Khung_KeHoach_Chuan!$A$11:$J$91, 5, FALSE) -> Chọn SDN controller, công cụ mô phỏng & kiến trúc hệ thống | D18: =VLOOKUP($L$4&"_"&$A18, Khung_KeHoach_Chuan!$A$11:$J$91, 6, FALSE) -> Controller (ONOS/Ryu/OpenDaylight), công cụ mô phỏng (Mininet/Containerlab/GNS3), giao thức điều khiển | E18: SDN Controller: Chọn ONOS do ưu điểm nhẹ, dễ lập trình kịch bản điều khiển bằng Python và hỗ trợ chuẩn OpenFlow v1.3. Công cụ mô phỏng: Sử dụng Mininet kết hợp với Open vSwitch (OVS) để tạo lập topo mạng ảo hóa cho các Router/Switch WAN. | F18: =VLOOKUP($L$4&"_"&$A18, Khung_KeHoach_Chuan!$A$11:$J$91, 7, FALSE) -> 2026-08-28 | G18: =VLOOKUP($L$4&"_"&$A18, Khung_KeHoach_Chuan!$A$11:$J$91, 8, FALSE) -> 2026-09-05 | H18: =VLOOKUP($L$4&"_"&$A18, Khung_KeHoach_Chuan!$A$11:$J$91, 9, FALSE) -> Sơ đồ kiến trúc tổng thể mạng + Tech stack specification | I18: Hoàn thành
A19: 4 | B19: =VLOOKUP($L$4&"_"&$A19, Khung_KeHoach_Chuan!$A$11:$J$91, 4, FALSE) -> I. ĐỊNH HƯỚNG & PHƯƠNG PHÁP LUẬN | C19: =VLOOKUP($L$4&"_"&$A19, Khung_KeHoach_Chuan!$A$11:$J$91, 5, FALSE) -> Lập kế hoạch công việc, phân công & quản trị rủi ro | D19: =VLOOKUP($L$4&"_"&$A19, Khung_KeHoach_Chuan!$A$11:$J$91, 6, FALSE) -> WBS: dựng testbed, lập trình controller, kiểm thử định tuyến; Git repo & quy ước làm việc | F19: =VLOOKUP($L$4&"_"&$A19, Khung_KeHoach_Chuan!$A$11:$J$91, 7, FALSE) -> 2026-08-30 | G19: =VLOOKUP($L$4&"_"&$A19, Khung_KeHoach_Chuan!$A$11:$J$91, 8, FALSE) -> 2026-09-05 | H19: =VLOOKUP($L$4&"_"&$A19, Khung_KeHoach_Chuan!$A$11:$J$91, 9, FALSE) -> WBS Backlog + Git repo setup + Quy ước làm việc | I19: Hoàn thành
A20: 5 | B20: =VLOOKUP($L$4&"_"&$A20, Khung_KeHoach_Chuan!$A$11:$J$91, 4, FALSE) -> II. THIẾT KẾ & CHUẨN BỊ | C20: =VLOOKUP($L$4&"_"&$A20, Khung_KeHoach_Chuan!$A$11:$J$91, 5, FALSE) -> Thiết kế topology mạng thử nghiệm & luồng điều khiển | D20: =VLOOKUP($L$4&"_"&$A20, Khung_KeHoach_Chuan!$A$11:$J$91, 6, FALSE) -> Sơ đồ topology SDN/SD-WAN, luồng traffic, cơ chế trao đổi control plane - data plane | F20: =VLOOKUP($L$4&"_"&$A20, Khung_KeHoach_Chuan!$A$11:$J$91, 7, FALSE) -> 2026-09-06 | G20: =VLOOKUP($L$4&"_"&$A20, Khung_KeHoach_Chuan!$A$11:$J$91, 8, FALSE) -> 2026-09-12 | H20: =VLOOKUP($L$4&"_"&$A20, Khung_KeHoach_Chuan!$A$11:$J$91, 9, FALSE) -> Sơ đồ topology mạng + Thiết kế luồng điều khiển v1 | I20: Hoàn thành
A21: 6 | B21: =VLOOKUP($L$4&"_"&$A21, Khung_KeHoach_Chuan!$A$11:$J$91, 4, FALSE) -> II. THIẾT KẾ & CHUẨN BỊ | C21: =VLOOKUP($L$4&"_"&$A21, Khung_KeHoach_Chuan!$A$11:$J$91, 5, FALSE) -> Chuẩn bị testbed, controller & công cụ giám sát mạng | D21: =VLOOKUP($L$4&"_"&$A21, Khung_KeHoach_Chuan!$A$11:$J$91, 6, FALSE) -> Cài đặt Mininet/Containerlab + controller, công cụ sinh traffic (iperf/hping3), giám sát (Wireshark) | F21: =VLOOKUP($L$4&"_"&$A21, Khung_KeHoach_Chuan!$A$11:$J$91, 7, FALSE) -> 2026-09-06 | G21: =VLOOKUP($L$4&"_"&$A21, Khung_KeHoach_Chuan!$A$11:$J$91, 8, FALSE) -> 2026-09-12 | H21: =VLOOKUP($L$4&"_"&$A21, Khung_KeHoach_Chuan!$A$11:$J$91, 9, FALSE) -> Testbed SDN/SD-WAN hoàn chỉnh + Công cụ giám sát | I21: Đang thực hiện
A22: 7 | B22: =VLOOKUP($L$4&"_"&$A22, Khung_KeHoach_Chuan!$A$11:$J$91, 4, FALSE) -> II. THIẾT KẾ & CHUẨN BỊ | C22: =VLOOKUP($L$4&"_"&$A22, Khung_KeHoach_Chuan!$A$11:$J$91, 5, FALSE) -> Xây dựng kế hoạch kiểm thử & tiêu chí nghiệm thu | D22: =VLOOKUP($L$4&"_"&$A22, Khung_KeHoach_Chuan!$A$11:$J$91, 6, FALSE) -> Test plan, kịch bản định tuyến/failover, tiêu chí đánh giá (Latency, Throughput, Packet Loss) | F22: =VLOOKUP($L$4&"_"&$A22, Khung_KeHoach_Chuan!$A$11:$J$91, 7, FALSE) -> 2026-09-13 | G22: =VLOOKUP($L$4&"_"&$A22, Khung_KeHoach_Chuan!$A$11:$J$91, 8, FALSE) -> 2026-09-19 | H22: =VLOOKUP($L$4&"_"&$A22, Khung_KeHoach_Chuan!$A$11:$J$91, 9, FALSE) -> Test plan + Bộ tiêu chí đánh giá + Baseline metrics | I22: Đang thực hiện
A23: 8 | B23: =VLOOKUP($L$4&"_"&$A23, Khung_KeHoach_Chuan!$A$11:$J$91, 4, FALSE) -> II. THIẾT KẾ & CHUẨN BỊ | C23: =VLOOKUP($L$4&"_"&$A23, Khung_KeHoach_Chuan!$A$11:$J$91, 5, FALSE) -> Làm Proof of Concept (PoC): điều khiển định tuyến cơ bản qua controller | D23: =VLOOKUP($L$4&"_"&$A23, Khung_KeHoach_Chuan!$A$11:$J$91, 6, FALSE) -> Cấu hình flow rules cơ bản, kiểm tra khả năng điều khiển luồng traffic qua controller | F23: =VLOOKUP($L$4&"_"&$A23, Khung_KeHoach_Chuan!$A$11:$J$91, 7, FALSE) -> 2026-09-13 | G23: =VLOOKUP($L$4&"_"&$A23, Khung_KeHoach_Chuan!$A$11:$J$91, 8, FALSE) -> 2026-09-19 | H23: =VLOOKUP($L$4&"_"&$A23, Khung_KeHoach_Chuan!$A$11:$J$91, 9, FALSE) -> Bản demo PoC điều khiển SDN chạy được + Báo cáo rủi ro kỹ thuật | I23: Đang thực hiện
A24: 9 | B24: =VLOOKUP($L$4&"_"&$A24, Khung_KeHoach_Chuan!$A$11:$J$91, 4, FALSE) -> III. TRIỂN KHAI / THỰC NGHIỆM | C24: =VLOOKUP($L$4&"_"&$A24, Khung_KeHoach_Chuan!$A$11:$J$91, 5, FALSE) -> Xây dựng phiên bản MVP: hệ thống SDN/SD-WAN vận hành cơ bản | D24: =VLOOKUP($L$4&"_"&$A24, Khung_KeHoach_Chuan!$A$11:$J$91, 6, FALSE) -> Hoàn thành luồng điều khiển - định tuyến - giám sát cơ bản trên toàn bộ topology | F24: =VLOOKUP($L$4&"_"&$A24, Khung_KeHoach_Chuan!$A$11:$J$91, 7, FALSE) -> 2026-09-20 | G24: =VLOOKUP($L$4&"_"&$A24, Khung_KeHoach_Chuan!$A$11:$J$91, 8, FALSE) -> 2026-09-26 | H24: =VLOOKUP($L$4&"_"&$A24, Khung_KeHoach_Chuan!$A$11:$J$91, 9, FALSE) -> Bản MVP: hệ thống SDN/SD-WAN chạy thông luồng cơ bản | I24: Đang thực hiện
A25: 10 | B25: =VLOOKUP($L$4&"_"&$A25, Khung_KeHoach_Chuan!$A$11:$J$91, 4, FALSE) -> III. TRIỂN KHAI / THỰC NGHIỆM | C25: =VLOOKUP($L$4&"_"&$A25, Khung_KeHoach_Chuan!$A$11:$J$91, 5, FALSE) -> NỘP BÁO CÁO TIẾN ĐỘ GIỮA KỲ (MỐC KHOA) | D25: =VLOOKUP($L$4&"_"&$A25, Khung_KeHoach_Chuan!$A$11:$J$91, 6, FALSE) -> Tổng hợp tiến độ thực hiện, nộp phiếu theo dõi có chữ ký GVHD | F25: =VLOOKUP($L$4&"_"&$A25, Khung_KeHoach_Chuan!$A$11:$J$91, 7, FALSE) -> 2026-09-20 | G25: =VLOOKUP($L$4&"_"&$A25, Khung_KeHoach_Chuan!$A$11:$J$91, 8, FALSE) -> 2026-10-04 | H25: =VLOOKUP($L$4&"_"&$A25, Khung_KeHoach_Chuan!$A$11:$J$91, 9, FALSE) -> Phiếu theo dõi có chữ ký GVHD + Báo cáo giữa kỳ ELIT | I25: Chưa bắt đầu
A26: 11 | B26: =VLOOKUP($L$4&"_"&$A26, Khung_KeHoach_Chuan!$A$11:$J$91, 4, FALSE) -> III. TRIỂN KHAI / THỰC NGHIỆM | C26: =VLOOKUP($L$4&"_"&$A26, Khung_KeHoach_Chuan!$A$11:$J$91, 5, FALSE) -> Phát triển hoàn thiện module định tuyến & chính sách điều khiển | D26: =VLOOKUP($L$4&"_"&$A26, Khung_KeHoach_Chuan!$A$11:$J$91, 6, FALSE) -> Lập trình logic định tuyến động, chính sách QoS/ưu tiên traffic, xử lý sự kiện mạng | F26: =VLOOKUP($L$4&"_"&$A26, Khung_KeHoach_Chuan!$A$11:$J$91, 7, FALSE) -> 2026-10-05 | G26: =VLOOKUP($L$4&"_"&$A26, Khung_KeHoach_Chuan!$A$11:$J$91, 8, FALSE) -> 2026-10-18 | H26: =VLOOKUP($L$4&"_"&$A26, Khung_KeHoach_Chuan!$A$11:$J$91, 9, FALSE) -> Module định tuyến & chính sách điều khiển hoàn chỉnh trên Git | I26: Chưa bắt đầu
A27: 12 | B27: =VLOOKUP($L$4&"_"&$A27, Khung_KeHoach_Chuan!$A$11:$J$91, 4, FALSE) -> III. TRIỂN KHAI / THỰC NGHIỆM | C27: =VLOOKUP($L$4&"_"&$A27, Khung_KeHoach_Chuan!$A$11:$J$91, 5, FALSE) -> Tích hợp toàn bộ hệ thống & đồng bộ cấu hình mạng | D27: =VLOOKUP($L$4&"_"&$A27, Khung_KeHoach_Chuan!$A$11:$J$91, 6, FALSE) -> Kết nối controller-switch-orchestrator, đồng bộ cấu hình giữa các site SD-WAN | F27: =VLOOKUP($L$4&"_"&$A27, Khung_KeHoach_Chuan!$A$11:$J$91, 7, FALSE) -> 2026-10-19 | G27: =VLOOKUP($L$4&"_"&$A27, Khung_KeHoach_Chuan!$A$11:$J$91, 8, FALSE) -> 2026-10-25 | H27: =VLOOKUP($L$4&"_"&$A27, Khung_KeHoach_Chuan!$A$11:$J$91, 9, FALSE) -> Hệ thống tích hợp hoàn chỉnh (Full System Build) | I27: Chưa bắt đầu
A28: 13 | B28: =VLOOKUP($L$4&"_"&$A28, Khung_KeHoach_Chuan!$A$11:$J$91, 4, FALSE) -> III. TRIỂN KHAI / THỰC NGHIỆM | C28: =VLOOKUP($L$4&"_"&$A28, Khung_KeHoach_Chuan!$A$11:$J$91, 5, FALSE) -> Duy trì Technical Log, Commit history & Bằng chứng | D28: =VLOOKUP($L$4&"_"&$A28, Khung_KeHoach_Chuan!$A$11:$J$91, 6, FALSE) -> Ghi log cấu hình controller, thay đổi flow rules, biên bản họp định kỳ với GVHD | F28: =VLOOKUP($L$4&"_"&$A28, Khung_KeHoach_Chuan!$A$11:$J$91, 7, FALSE) -> 2026-09-20 | G28: =VLOOKUP($L$4&"_"&$A28, Khung_KeHoach_Chuan!$A$11:$J$91, 8, FALSE) -> 2026-10-31 | H28: =VLOOKUP($L$4&"_"&$A28, Khung_KeHoach_Chuan!$A$11:$J$91, 9, FALSE) -> Thư mục Evidence + Git commit log chuẩn quy cách | I28: Chưa bắt đầu
A29: 14 | B29: =VLOOKUP($L$4&"_"&$A29, Khung_KeHoach_Chuan!$A$11:$J$91, 4, FALSE) -> IV. KIỂM THỬ & ĐÁNH GIÁ | C29: =VLOOKUP($L$4&"_"&$A29, Khung_KeHoach_Chuan!$A$11:$J$91, 5, FALSE) -> Thực thi kiểm thử chức năng hệ thống SDN/SD-WAN | D29: =VLOOKUP($L$4&"_"&$A29, Khung_KeHoach_Chuan!$A$11:$J$91, 6, FALSE) -> Kiểm tra định tuyến, failover, chính sách QoS, khả năng phản hồi controller | F29: =VLOOKUP($L$4&"_"&$A29, Khung_KeHoach_Chuan!$A$11:$J$91, 7, FALSE) -> 2026-10-26 | G29: =VLOOKUP($L$4&"_"&$A29, Khung_KeHoach_Chuan!$A$11:$J$91, 8, FALSE) -> 2026-11-01 | H29: =VLOOKUP($L$4&"_"&$A29, Khung_KeHoach_Chuan!$A$11:$J$91, 9, FALSE) -> Bảng kết quả test chi tiết + Danh sách lỗi đã xử lý | I29: Chưa bắt đầu
A30: 15 | B30: =VLOOKUP($L$4&"_"&$A30, Khung_KeHoach_Chuan!$A$11:$J$91, 4, FALSE) -> IV. KIỂM THỬ & ĐÁNH GIÁ | C30: =VLOOKUP($L$4&"_"&$A30, Khung_KeHoach_Chuan!$A$11:$J$91, 5, FALSE) -> Kiểm thử hiệu năng, độ trễ & khả năng mở rộng hệ thống | D30: =VLOOKUP($L$4&"_"&$A30, Khung_KeHoach_Chuan!$A$11:$J$91, 6, FALSE) -> Đo độ trễ xử lý (latency), thông lượng (throughput), khả năng chịu tải | F30: =VLOOKUP($L$4&"_"&$A30, Khung_KeHoach_Chuan!$A$11:$J$91, 7, FALSE) -> 2026-11-02 | G30: =VLOOKUP($L$4&"_"&$A30, Khung_KeHoach_Chuan!$A$11:$J$91, 8, FALSE) -> 2026-11-08 | H30: =VLOOKUP($L$4&"_"&$A30, Khung_KeHoach_Chuan!$A$11:$J$91, 9, FALSE) -> Báo cáo Performance & Scalability testing | I30: Chưa bắt đầu
... A42: 27 | B42: =VLOOKUP($L$4&"_"&$A42, Khung_KeHoach_Chuan!$A$11:$J$91, 4, FALSE) -> VI. ĐÓNG GÓI, BÁO CÁO & ĐÁNH GIÁ RUBRIC | C42: =VLOOKUP($L$4&"_"&$A42, Khung_KeHoach_Chuan!$A$11:$J$91, 5, FALSE) -> BÁO CÁO VỚI GVPB & NHẬP ĐIỂM RUBRIC | D42: =VLOOKUP($L$4&"_"&$A42, Khung_KeHoach_Chuan!$A$11:$J$91, 6, FALSE) -> Báo cáo trực tiếp với GVPB; GVPB và GVHD thống nhất điểm trên Rubric | F42: =VLOOKUP($L$4&"_"&$A42, Khung_KeHoach_Chuan!$A$11:$J$91, 7, FALSE) -> 2026-12-26 | G42: =VLOOKUP($L$4&"_"&$A42, Khung_KeHoach_Chuan!$A$11:$J$91, 8, FALSE) -> 2026-12-31 | H42: =VLOOKUP($L$4&"_"&$A42, Khung_KeHoach_Chuan!$A$11:$J$91, 9, FALSE) -> Hoàn thành bảo vệ & Điểm số Rubric chính thức | I42: Chưa bắt đầu
A43: KHỐI CÔNG VIỆC - LOẠI HÌNH THỨ 2 (CHỈ DÙNG NẾU NHÓM LÀM ĐỒNG THỜI 2 LOẠI HÌNH)
A44: STT | B44: Giai Đoạn | C44: Hạng Mục Công Việc | D44: Nội Dung Cần Thực Hiện / Gợi Ý | E44: Nội Dung Nhóm Tự Điền | F44: Bắt Đầu | G44: Hạn Hoàn Thành | H44: Kết Quả Đầu Ra Gợi Ý | I44: Trạng Thái (*) | J44: Người Phụ Trách / Ghi Chú & Link
A45: 1 | B45: =IFERROR(VLOOKUP($C$10&"_"&$A45, Khung_KeHoach_Chuan!$A$11:$J$91, 4, FALSE),"") | C45: =IFERROR(VLOOKUP($C$10&"_"&$A45, Khung_KeHoach_Chuan!$A$11:$J$91, 5, FALSE),"") | D45: =IFERROR(VLOOKUP($C$10&"_"&$A45, Khung_KeHoach_Chuan!$A$11:$J$91, 6, FALSE),"") | F45: =IFERROR(VLOOKUP($C$10&"_"&$A45, Khung_KeHoach_Chuan!$A$11:$J$91, 7, FALSE),"") | G45: =IFERROR(VLOOKUP($C$10&"_"&$A45, Khung_KeHoach_Chuan!$A$11:$J$91, 8, FALSE),"") | H45: =IFERROR(VLOOKUP($C$10&"_"&$A45, Khung_KeHoach_Chuan!$A$11:$J$91, 9, FALSE),"") | I45: Chưa bắt đầu
A46: 2 | B46: =IFERROR(VLOOKUP($C$10&"_"&$A46, Khung_KeHoach_Chuan!$A$11:$J$91, 4, FALSE),"") | C46: =IFERROR(VLOOKUP($C$10&"_"&$A46, Khung_KeHoach_Chuan!$A$11:$J$91, 5, FALSE),"") | D46: =IFERROR(VLOOKUP($C$10&"_"&$A46, Khung_KeHoach_Chuan!$A$11:$J$91, 6, FALSE),"") | F46: =IFERROR(VLOOKUP($C$10&"_"&$A46, Khung_KeHoach_Chuan!$A$11:$J$91, 7, FALSE),"") | G46: =IFERROR(VLOOKUP($C$10&"_"&$A46, Khung_KeHoach_Chuan!$A$11:$J$91, 8, FALSE),"") | H46: =IFERROR(VLOOKUP($C$10&"_"&$A46, Khung_KeHoach_Chuan!$A$11:$J$91, 9, FALSE),"") | I46: Chưa bắt đầu
A47: 3 | B47: =IFERROR(VLOOKUP($C$10&"_"&$A47, Khung_KeHoach_Chuan!$A$11:$J$91, 4, FALSE),"") | C47: =IFERROR(VLOOKUP($C$10&"_"&$A47, Khung_KeHoach_Chuan!$A$11:$J$91, 5, FALSE),"") | D47: =IFERROR(VLOOKUP($C$10&"_"&$A47, Khung_KeHoach_Chuan!$A$11:$J$91, 6, FALSE),"") | F47: =IFERROR(VLOOKUP($C$10&"_"&$A47, Khung_KeHoach_Chuan!$A$11:$J$91, 7, FALSE),"") | G47: =IFERROR(VLOOKUP($C$10&"_"&$A47, Khung_KeHoach_Chuan!$A$11:$J$91, 8, FALSE),"") | H47: =IFERROR(VLOOKUP($C$10&"_"&$A47, Khung_KeHoach_Chuan!$A$11:$J$91, 9, FALSE),"") | I47: Chưa bắt đầu
A48: 4 | B48: =IFERROR(VLOOKUP($C$10&"_"&$A48, Khung_KeHoach_Chuan!$A$11:$J$91, 4, FALSE),"") | C48: =IFERROR(VLOOKUP($C$10&"_"&$A48, Khung_KeHoach_Chuan!$A$11:$J$91, 5, FALSE),"") | D48: =IFERROR(VLOOKUP($C$10&"_"&$A48, Khung_KeHoach_Chuan!$A$11:$J$91, 6, FALSE),"") | F48: =IFERROR(VLOOKUP($C$10&"_"&$A48, Khung_KeHoach_Chuan!$A$11:$J$91, 7, FALSE),"") | G48: =IFERROR(VLOOKUP($C$10&"_"&$A48, Khung_KeHoach_Chuan!$A$11:$J$91, 8, FALSE),"") | H48: =IFERROR(VLOOKUP($C$10&"_"&$A48, Khung_KeHoach_Chuan!$A$11:$J$91, 9, FALSE),"") | I48: Chưa bắt đầu
A49: 5 | B49: =IFERROR(VLOOKUP($C$10&"_"&$A49, Khung_KeHoach_Chuan!$A$11:$J$91, 4, FALSE),"") | C49: =IFERROR(VLOOKUP($C$10&"_"&$A49, Khung_KeHoach_Chuan!$A$11:$J$91, 5, FALSE),"") | D49: =IFERROR(VLOOKUP($C$10&"_"&$A49, Khung_KeHoach_Chuan!$A$11:$J$91, 6, FALSE),"") | F49: =IFERROR(VLOOKUP($C$10&"_"&$A49, Khung_KeHoach_Chuan!$A$11:$J$91, 7, FALSE),"") | G49: =IFERROR(VLOOKUP($C$10&"_"&$A49, Khung_KeHoach_Chuan!$A$11:$J$91, 8, FALSE),"") | H49: =IFERROR(VLOOKUP($C$10&"_"&$A49, Khung_KeHoach_Chuan!$A$11:$J$91, 9, FALSE),"") | I49: Chưa bắt đầu
A50: 6 | B50: =IFERROR(VLOOKUP($C$10&"_"&$A50, Khung_KeHoach_Chuan!$A$11:$J$91, 4, FALSE),"") | C50: =IFERROR(VLOOKUP($C$10&"_"&$A50, Khung_KeHoach_Chuan!$A$11:$J$91, 5, FALSE),"") | D50: =IFERROR(VLOOKUP($C$10&"_"&$A50, Khung_KeHoach_Chuan!$A$11:$J$91, 6, FALSE),"") | F50: =IFERROR(VLOOKUP($C$10&"_"&$A50, Khung_KeHoach_Chuan!$A$11:$J$91, 7, FALSE),"") | G50: =IFERROR(VLOOKUP($C$10&"_"&$A50, Khung_KeHoach_Chuan!$A$11:$J$91, 8, FALSE),"") | H50: =IFERROR(VLOOKUP($C$10&"_"&$A50, Khung_KeHoach_Chuan!$A$11:$J$91, 9, FALSE),"") | I50: Chưa bắt đầu
A51: 7 | B51: =IFERROR(VLOOKUP($C$10&"_"&$A51, Khung_KeHoach_Chuan!$A$11:$J$91, 4, FALSE),"") | C51: =IFERROR(VLOOKUP($C$10&"_"&$A51, Khung_KeHoach_Chuan!$A$11:$J$91, 5, FALSE),"") | D51: =IFERROR(VLOOKUP($C$10&"_"&$A51, Khung_KeHoach_Chuan!$A$11:$J$91, 6, FALSE),"") | F51: =IFERROR(VLOOKUP($C$10&"_"&$A51, Khung_KeHoach_Chuan!$A$11:$J$91, 7, FALSE),"") | G51: =IFERROR(VLOOKUP($C$10&"_"&$A51, Khung_KeHoach_Chuan!$A$11:$J$91, 8, FALSE),"") | H51: =IFERROR(VLOOKUP($C$10&"_"&$A51, Khung_KeHoach_Chuan!$A$11:$J$91, 9, FALSE),"") | I51: Chưa bắt đầu
A52: 8 | B52: =IFERROR(VLOOKUP($C$10&"_"&$A52, Khung_KeHoach_Chuan!$A$11:$J$91, 4, FALSE),"") | C52: =IFERROR(VLOOKUP($C$10&"_"&$A52, Khung_KeHoach_Chuan!$A$11:$J$91, 5, FALSE),"") | D52: =IFERROR(VLOOKUP($C$10&"_"&$A52, Khung_KeHoach_Chuan!$A$11:$J$91, 6, FALSE),"") | F52: =IFERROR(VLOOKUP($C$10&"_"&$A52, Khung_KeHoach_Chuan!$A$11:$J$91, 7, FALSE),"") | G52: =IFERROR(VLOOKUP($C$10&"_"&$A52, Khung_KeHoach_Chuan!$A$11:$J$91, 8, FALSE),"") | H52: =IFERROR(VLOOKUP($C$10&"_"&$A52, Khung_KeHoach_Chuan!$A$11:$J$91, 9, FALSE),"") | I52: Chưa bắt đầu
A53: 9 | B53: =IFERROR(VLOOKUP($C$10&"_"&$A53, Khung_KeHoach_Chuan!$A$11:$J$91, 4, FALSE),"") | C53: =IFERROR(VLOOKUP($C$10&"_"&$A53, Khung_KeHoach_Chuan!$A$11:$J$91, 5, FALSE),"") | D53: =IFERROR(VLOOKUP($C$10&"_"&$A53, Khung_KeHoach_Chuan!$A$11:$J$91, 6, FALSE),"") | F53: =IFERROR(VLOOKUP($C$10&"_"&$A53, Khung_KeHoach_Chuan!$A$11:$J$91, 7, FALSE),"") | G53: =IFERROR(VLOOKUP($C$10&"_"&$A53, Khung_KeHoach_Chuan!$A$11:$J$91, 8, FALSE),"") | H53: =IFERROR(VLOOKUP($C$10&"_"&$A53, Khung_KeHoach_Chuan!$A$11:$J$91, 9, FALSE),"") | I53: Chưa bắt đầu
...

Sheet Nhom_03
A1: BẢNG THEO DÕI TIẾN ĐỘ THỰC HIỆN ĐỀ TÀI - NHÓM 03
A2: Khoa Công nghệ Thông tin - Trường ĐH Tôn Đức Thắng | Học kỳ 1 / Năm học 2026 - 2027
A4: Loại hình đề tài (*): | C4: Dự án CNTT | F4: GV Hướng dẫn: | G4: ThS. Lê Viết Thanh | L4: =IF(OR($C$4="Dự án + Đồ án",$C$4="Dự án + Khóa luận"),"Dự án CNTT",$C$4) -> Dự án CNTT
A5: Tên đề tài / dự án: | C5: QUẢN LÝ MẠNG DOANH NGHIỆP TRÊN NỀN TẢNG CLOUD SỬ DỤNG SDN
A6: Sinh viên 1 (Trưởng nhóm): | C6: Đỗ Tài Khải Nguyên - 52300230 | F6: Sinh viên 2: | G6: Nguyễn Văn An - 52300172
A7: Email / SĐT SV 1: | C7: 52300230Âstudent.tdtu.edu.vn | F7: Email / SĐT SV 2: | G7: 52300172@student.tdtu.edu.vn
A8: Ngày bắt đầu: | C8: =VLOOKUP($L$4, Khung_KeHoach_Chuan!$A$5:$H$7, 2, FALSE) -> 2026-08-24 | F8: Báo cáo sạch hoàn tất: | G8: =VLOOKUP($L$4, Khung_KeHoach_Chuan!$A$5:$H$7, 4, FALSE) -> 2026-11-20
A9: Deadline chính thức: | C9: =VLOOKUP($L$4, Khung_KeHoach_Chuan!$A$5:$H$7, 5, FALSE) -> 2026-12-04 | F9: Lịch Phản biện / Bảo vệ: | G9: =VLOOKUP($L$4, Khung_KeHoach_Chuan!$A$5:$H$7, 7, FALSE) -> 26/12/2026 – 31/12/2026
A10: Loại hình thứ 2 (nếu có):
A11: TỔNG QUAN TIẾN ĐỘ THỰC HIỆN CỦA NHÓM
A12: Tổng Hạng Mục | B12: Hoàn Thành | C12: Đang Làm | D12: Chưa Bắt Đầu | F12: Tạm Hoãn | G12: Báo Cáo Sạch | H12: Tỷ Lệ Hoàn Thành | I12: Trạng Thái Chung
A13: =COUNTA(C16:C42) + IF($C$10<>"", COUNTA(C45:C71), 0) -> 27 | B13: =COUNTIF(I16:I42, "Hoàn thành") + IF($C$10<>"", COUNTIF(I45:I71, "Hoàn thành"), 0) -> 8 | C13: =COUNTIF(I16:I42, "Đang thực hiện") + IF($C$10<>"", COUNTIF(I45:I71, "Đang thực hiện"), 0) -> 1 | D13: =COUNTIF(I16:I42, "Chưa bắt đầu") + IF($C$10<>"", COUNTIF(I45:I71, "Chưa bắt đầu"), 0) -> 18 | F13: =COUNTIF(I16:I42, "Tạm hoãn - Bị chặn") + IF($C$10<>"", COUNTIF(I45:I71, "Tạm hoãn - Bị chặn"), 0) -> 0 | G13: =G8 -> 2026-11-20 | H13: =B13/A13 -> 0.2962963 | I13: =IF(H13=1, "ĐÃ HOÀN TẤT", IF(H13>=0.5, "ĐANG ĐÚNG HẠN", IF(F13>0, "CẦN HỖ TRỢ", "ĐANG THỰC HIỆN"))) -> ĐANG THỰC HIỆN
A15: STT | B15: Giai Đoạn | C15: Hạng Mục Công Việc | D15: Nội Dung Cần Thực Hiện / Gợi Ý | E15: Nội Dung Nhóm Tự Điền | F15: Bắt Đầu | G15: Hạn Hoàn Thành | H15: Kết Quả Đầu Ra Gợi Ý | I15: Trạng Thái (*) | J15: Người Phụ Trách / Ghi Chú & Link
A16: 1 | B16: =VLOOKUP($L$4&"_"&$A16, Khung_KeHoach_Chuan!$A$11:$J$91, 4, FALSE) -> I. ĐỊNH HƯỚNG & PHƯƠNG PHÁP LUẬN | C16: Xác định bài toán mạng & mục tiêu | D16: Đã xác định bài toán quản lý mạng doanh nghiệp tập trung, kết hợp SDN cho mạng LAN và SD-WAN cho kết nối giữa HQ/Branch; xác định phạm vi mô phỏng trên Mininet. | F16: =VLOOKUP($L$4&"_"&$A16, Khung_KeHoach_Chuan!$A$11:$J$91, 7, FALSE) -> 2026-08-24 | G16: =VLOOKUP($L$4&"_"&$A16, Khung_KeHoach_Chuan!$A$11:$J$91, 8, FALSE) -> 2026-08-28 | H16: Xác định bài toán, mục tiêu và phạm vi của đề tài. | I16: Hoàn thành
A17: 2 | B17: =VLOOKUP($L$4&"_"&$A17, Khung_KeHoach_Chuan!$A$11:$J$91, 4, FALSE) -> I. ĐỊNH HƯỚNG & PHƯƠNG PHÁP LUẬN | C17: Khảo sát kiến trúc SDN/SD-WAN | D17: Đã nghiên cứu kiến trúc SDN, SD-WAN, OpenFlow, VLAN, Underlay/Overlay và cơ chế Controller quản lý tập trung thiết bị mạng. | F17: =VLOOKUP($L$4&"_"&$A17, Khung_KeHoach_Chuan!$A$11:$J$91, 7, FALSE) -> 2026-08-24 | G17: =VLOOKUP($L$4&"_"&$A17, Khung_KeHoach_Chuan!$A$11:$J$91, 8, FALSE) -> 2026-09-02 | H17: Tài liệu tổng hợp kiến thức về SDN, SD-WAN, OpenFlow, VLAN và các công nghệ liên quan. | I17: Hoàn thành
